admin Alterou uma cto: 13604/04/2022, 15:30:27
admin Alterou uma cto: ID:136 04/04/2022, 15:34:19
admin alterou a cto de ID:364 na data:  04/04/2022, 15:36:52
Internal Server Error: /admin/components/ruas/
Traceback (most recent call last):
  File "C:\projetos\speednetwork\venv\lib\site-packages\django\core\handlers\exception.py", line 34, in inner
    response = get_response(request)
  File "C:\projetos\speednetwork\venv\lib\site-packages\django\core\handlers\base.py", line 115, in _get_response
    response = self.process_exception_by_middleware(e, request)
  File "C:\projetos\speednetwork\venv\lib\site-packages\django\core\handlers\base.py", line 113, in _get_response
    response = wrapped_callback(request, *callback_args, **callback_kwargs)
  File "C:\projetos\speednetwork\venv\lib\site-packages\django\contrib\admin\options.py", line 607, in wrapper
    return self.admin_site.admin_view(view)(*args, **kwargs)
  File "C:\projetos\speednetwork\venv\lib\site-packages\django\utils\decorators.py", line 130, in _wrapped_view
    response = view_func(request, *args, **kwargs)
  File "C:\projetos\speednetwork\venv\lib\site-packages\django\views\decorators\cache.py", line 44, in _wrapped_view_func
    response = view_func(request, *args, **kwargs)
  File "C:\projetos\speednetwork\venv\lib\site-packages\django\contrib\admin\sites.py", line 231, in inner
    return view(request, *args, **kwargs)
  File "C:\projetos\speednetwork\venv\lib\site-packages\django\utils\decorators.py", line 43, in _wrapper
    return bound_method(*args, **kwargs)
  File "C:\projetos\speednetwork\venv\lib\site-packages\django\utils\decorators.py", line 130, in _wrapped_view
    response = view_func(request, *args, **kwargs)
  File "C:\projetos\speednetwork\venv\lib\site-packages\django\contrib\admin\options.py", line 1678, in changelist_view
    cl = self.get_changelist_instance(request)
  File "C:\projetos\speednetwork\venv\lib\site-packages\django\contrib\admin\options.py", line 728, in get_changelist_instance
    return ChangeList(
  File "C:\projetos\speednetwork\venv\lib\site-packages\django\contrib\admin\views\main.py", line 97, in __init__
    self.queryset = self.get_queryset(request)
  File "C:\projetos\speednetwork\venv\lib\site-packages\django\contrib\admin\views\main.py", line 457, in get_queryset
    qs, search_use_distinct = self.model_admin.get_search_results(request, qs, self.query)
  File "C:\projetos\speednetwork\venv\lib\site-packages\django\contrib\admin\options.py", line 1016, in get_search_results
    queryset = queryset.filter(reduce(operator.or_, or_queries))
  File "C:\projetos\speednetwork\venv\lib\site-packages\django\db\models\query.py", line 904, in filter
    return self._filter_or_exclude(False, *args, **kwargs)
  File "C:\projetos\speednetwork\venv\lib\site-packages\django\db\models\query.py", line 923, in _filter_or_exclude
    clone.query.add_q(Q(*args, **kwargs))
  File "C:\projetos\speednetwork\venv\lib\site-packages\django\db\models\sql\query.py", line 1337, in add_q
    clause, _ = self._add_q(q_object, self.used_aliases)
  File "C:\projetos\speednetwork\venv\lib\site-packages\django\db\models\sql\query.py", line 1357, in _add_q
    child_clause, needed_inner = self._add_q(
  File "C:\projetos\speednetwork\venv\lib\site-packages\django\db\models\sql\query.py", line 1362, in _add_q
    child_clause, needed_inner = self.build_filter(
  File "C:\projetos\speednetwork\venv\lib\site-packages\django\db\models\sql\query.py", line 1298, in build_filter
    condition = self.build_lookup(lookups, col, value)
  File "C:\projetos\speednetwork\venv\lib\site-packages\django\db\models\sql\query.py", line 1146, in build_lookup
    raise FieldError('Related Field got invalid lookup: {}'.format(lookup_name))
django.core.exceptions.FieldError: Related Field got invalid lookup: icontains
"GET /admin/components/ruas/?q=ar HTTP/1.1" 500 167421
Internal Server Error: /api/lista-servicos-api/
Traceback (most recent call last):
  File "C:\projetos\speednetwork\venv\lib\site-packages\django\core\handlers\exception.py", line 34, in inner
    response = get_response(request)
  File "C:\projetos\speednetwork\venv\lib\site-packages\django\core\handlers\base.py", line 115, in _get_response
    response = self.process_exception_by_middleware(e, request)
  File "C:\projetos\speednetwork\venv\lib\site-packages\django\core\handlers\base.py", line 113, in _get_response
    response = wrapped_callback(request, *callback_args, **callback_kwargs)
  File "C:\projetos\speednetwork\venv\lib\site-packages\django\views\decorators\csrf.py", line 54, in wrapped_view
    return view_func(*args, **kwargs)
  File "C:\projetos\speednetwork\venv\lib\site-packages\rest_framework\viewsets.py", line 125, in view
    return self.dispatch(request, *args, **kwargs)
  File "C:\projetos\speednetwork\venv\lib\site-packages\rest_framework\views.py", line 509, in dispatch
    response = self.handle_exception(exc)
  File "C:\projetos\speednetwork\venv\lib\site-packages\rest_framework\views.py", line 469, in handle_exception
    self.raise_uncaught_exception(exc)
  File "C:\projetos\speednetwork\venv\lib\site-packages\rest_framework\views.py", line 480, in raise_uncaught_exception
    raise exc
  File "C:\projetos\speednetwork\venv\lib\site-packages\rest_framework\views.py", line 506, in dispatch
    response = handler(request, *args, **kwargs)
  File "C:\projetos\speednetwork\venv\lib\site-packages\rest_framework\mixins.py", line 46, in list
    return Response(serializer.data)
  File "C:\projetos\speednetwork\venv\lib\site-packages\rest_framework\serializers.py", line 745, in data
    ret = super().data
  File "C:\projetos\speednetwork\venv\lib\site-packages\rest_framework\serializers.py", line 246, in data
    self._data = self.to_representation(self.instance)
  File "C:\projetos\speednetwork\venv\lib\site-packages\rest_framework\serializers.py", line 663, in to_representation
    return [
  File "C:\projetos\speednetwork\venv\lib\site-packages\rest_framework\serializers.py", line 664, in <listcomp>
    self.child.to_representation(item) for item in iterable
  File "C:\projetos\speednetwork\venv\lib\site-packages\rest_framework\serializers.py", line 500, in to_representation
    for field in fields:
  File "C:\projetos\speednetwork\venv\lib\site-packages\rest_framework\serializers.py", line 361, in _readable_fields
    for field in self.fields.values():
  File "C:\projetos\speednetwork\venv\lib\site-packages\django\utils\functional.py", line 48, in __get__
    res = instance.__dict__[self.name] = self.func(instance)
  File "C:\projetos\speednetwork\venv\lib\site-packages\rest_framework\serializers.py", line 349, in fields
    for key, value in self.get_fields().items():
  File "C:\projetos\speednetwork\venv\lib\site-packages\rest_framework\serializers.py", line 1029, in get_fields
    field_names = self.get_field_names(declared_fields, info)
  File "C:\projetos\speednetwork\venv\lib\site-packages\rest_framework\serializers.py", line 1125, in get_field_names
    assert field_name in fields, (
AssertionError: The field 'categoria' was declared on serializer ServicesSerializer, but has not been included in the 'fields' option.
"GET /api/lista-servicos-api/ HTTP/1.1" 500 157338
Internal Server Error: /api/lista-servicos-api/
Traceback (most recent call last):
  File "C:\projetos\speednetwork\venv\lib\site-packages\django\core\handlers\exception.py", line 34, in inner
    response = get_response(request)
  File "C:\projetos\speednetwork\venv\lib\site-packages\django\core\handlers\base.py", line 115, in _get_response
    response = self.process_exception_by_middleware(e, request)
  File "C:\projetos\speednetwork\venv\lib\site-packages\django\core\handlers\base.py", line 113, in _get_response
    response = wrapped_callback(request, *callback_args, **callback_kwargs)
  File "C:\projetos\speednetwork\venv\lib\site-packages\django\views\decorators\csrf.py", line 54, in wrapped_view
    return view_func(*args, **kwargs)
  File "C:\projetos\speednetwork\venv\lib\site-packages\rest_framework\viewsets.py", line 125, in view
    return self.dispatch(request, *args, **kwargs)
  File "C:\projetos\speednetwork\venv\lib\site-packages\rest_framework\views.py", line 509, in dispatch
    response = self.handle_exception(exc)
  File "C:\projetos\speednetwork\venv\lib\site-packages\rest_framework\views.py", line 469, in handle_exception
    self.raise_uncaught_exception(exc)
  File "C:\projetos\speednetwork\venv\lib\site-packages\rest_framework\views.py", line 480, in raise_uncaught_exception
    raise exc
  File "C:\projetos\speednetwork\venv\lib\site-packages\rest_framework\views.py", line 506, in dispatch
    response = handler(request, *args, **kwargs)
  File "C:\projetos\speednetwork\venv\lib\site-packages\rest_framework\mixins.py", line 46, in list
    return Response(serializer.data)
  File "C:\projetos\speednetwork\venv\lib\site-packages\rest_framework\serializers.py", line 745, in data
    ret = super().data
  File "C:\projetos\speednetwork\venv\lib\site-packages\rest_framework\serializers.py", line 246, in data
    self._data = self.to_representation(self.instance)
  File "C:\projetos\speednetwork\venv\lib\site-packages\rest_framework\serializers.py", line 663, in to_representation
    return [
  File "C:\projetos\speednetwork\venv\lib\site-packages\rest_framework\serializers.py", line 664, in <listcomp>
    self.child.to_representation(item) for item in iterable
  File "C:\projetos\speednetwork\venv\lib\site-packages\rest_framework\serializers.py", line 500, in to_representation
    for field in fields:
  File "C:\projetos\speednetwork\venv\lib\site-packages\rest_framework\serializers.py", line 361, in _readable_fields
    for field in self.fields.values():
  File "C:\projetos\speednetwork\venv\lib\site-packages\django\utils\functional.py", line 48, in __get__
    res = instance.__dict__[self.name] = self.func(instance)
  File "C:\projetos\speednetwork\venv\lib\site-packages\rest_framework\serializers.py", line 349, in fields
    for key, value in self.get_fields().items():
  File "C:\projetos\speednetwork\venv\lib\site-packages\rest_framework\serializers.py", line 1029, in get_fields
    field_names = self.get_field_names(declared_fields, info)
  File "C:\projetos\speednetwork\venv\lib\site-packages\rest_framework\serializers.py", line 1125, in get_field_names
    assert field_name in fields, (
AssertionError: The field 'categoria' was declared on serializer ServicesSerializer, but has not been included in the 'fields' option.
"GET /api/lista-servicos-api/ HTTP/1.1" 500 157338
Internal Server Error: /servicos/api/list-service
Traceback (most recent call last):
  File "C:\projetos\speednetwork\venv\lib\site-packages\django\db\backends\utils.py", line 86, in _execute
    return self.cursor.execute(sql, params)
  File "C:\projetos\speednetwork\venv\lib\site-packages\django\db\backends\sqlite3\base.py", line 396, in execute
    return Database.Cursor.execute(self, query, params)
sqlite3.IntegrityError: NOT NULL constraint failed: services_servico.categoria_id

The above exception was the direct cause of the following exception:

Traceback (most recent call last):
  File "C:\projetos\speednetwork\venv\lib\site-packages\django\core\handlers\exception.py", line 34, in inner
    response = get_response(request)
  File "C:\projetos\speednetwork\venv\lib\site-packages\django\core\handlers\base.py", line 115, in _get_response
    response = self.process_exception_by_middleware(e, request)
  File "C:\projetos\speednetwork\venv\lib\site-packages\django\core\handlers\base.py", line 113, in _get_response
    response = wrapped_callback(request, *callback_args, **callback_kwargs)
  File "C:\projetos\speednetwork\venv\lib\site-packages\django\views\decorators\csrf.py", line 54, in wrapped_view
    return view_func(*args, **kwargs)
  File "C:\projetos\speednetwork\venv\lib\site-packages\django\views\generic\base.py", line 71, in view
    return self.dispatch(request, *args, **kwargs)
  File "C:\projetos\speednetwork\venv\lib\site-packages\rest_framework\views.py", line 509, in dispatch
    response = self.handle_exception(exc)
  File "C:\projetos\speednetwork\venv\lib\site-packages\rest_framework\views.py", line 469, in handle_exception
    self.raise_uncaught_exception(exc)
  File "C:\projetos\speednetwork\venv\lib\site-packages\rest_framework\views.py", line 480, in raise_uncaught_exception
    raise exc
  File "C:\projetos\speednetwork\venv\lib\site-packages\rest_framework\views.py", line 506, in dispatch
    response = handler(request, *args, **kwargs)
  File "C:\projetos\speednetwork\venv\lib\site-packages\rest_framework\decorators.py", line 50, in handler
    return func(*args, **kwargs)
  File "C:\projetos\speednetwork\apps\services\api\viewsets.py", line 18, in service_list
    serializer.save()
  File "C:\projetos\speednetwork\venv\lib\site-packages\rest_framework\serializers.py", line 205, in save
    self.instance = self.create(validated_data)
  File "C:\projetos\speednetwork\venv\lib\site-packages\rest_framework\serializers.py", line 939, in create
    instance = ModelClass._default_manager.create(**validated_data)
  File "C:\projetos\speednetwork\venv\lib\site-packages\django\db\models\manager.py", line 82, in manager_method
    return getattr(self.get_queryset(), name)(*args, **kwargs)
  File "C:\projetos\speednetwork\venv\lib\site-packages\django\db\models\query.py", line 433, in create
    obj.save(force_insert=True, using=self.db)
  File "C:\projetos\speednetwork\venv\lib\site-packages\django\db\models\base.py", line 745, in save
    self.save_base(using=using, force_insert=force_insert,
  File "C:\projetos\speednetwork\venv\lib\site-packages\django\db\models\base.py", line 782, in save_base
    updated = self._save_table(
  File "C:\projetos\speednetwork\venv\lib\site-packages\django\db\models\base.py", line 886, in _save_table
    results = self._do_insert(cls._base_manager, using, fields, returning_fields, raw)
  File "C:\projetos\speednetwork\venv\lib\site-packages\django\db\models\base.py", line 923, in _do_insert
    return manager._insert(
  File "C:\projetos\speednetwork\venv\lib\site-packages\django\db\models\manager.py", line 82, in manager_method
    return getattr(self.get_queryset(), name)(*args, **kwargs)
  File "C:\projetos\speednetwork\venv\lib\site-packages\django\db\models\query.py", line 1204, in _insert
    return query.get_compiler(using=using).execute_sql(returning_fields)
  File "C:\projetos\speednetwork\venv\lib\site-packages\django\db\models\sql\compiler.py", line 1377, in execute_sql
    cursor.execute(sql, params)
  File "C:\projetos\speednetwork\venv\lib\site-packages\django\db\backends\utils.py", line 100, in execute
    return super().execute(sql, params)
  File "C:\projetos\speednetwork\venv\lib\site-packages\django\db\backends\utils.py", line 68, in execute
    return self._execute_with_wrappers(sql, params, many=False, executor=self._execute)
  File "C:\projetos\speednetwork\venv\lib\site-packages\django\db\backends\utils.py", line 77, in _execute_with_wrappers
    return executor(sql, params, many, context)
  File "C:\projetos\speednetwork\venv\lib\site-packages\django\db\backends\utils.py", line 86, in _execute
    return self.cursor.execute(sql, params)
  File "C:\projetos\speednetwork\venv\lib\site-packages\django\db\utils.py", line 90, in __exit__
    raise dj_exc_value.with_traceback(traceback) from exc_value
  File "C:\projetos\speednetwork\venv\lib\site-packages\django\db\backends\utils.py", line 86, in _execute
    return self.cursor.execute(sql, params)
  File "C:\projetos\speednetwork\venv\lib\site-packages\django\db\backends\sqlite3\base.py", line 396, in execute
    return Database.Cursor.execute(self, query, params)
django.db.utils.IntegrityError: NOT NULL constraint failed: services_servico.categoria_id
"POST /servicos/api/list-service HTTP/1.1" 500 223474
Internal Server Error: /servicos/api/
Traceback (most recent call last):
  File "C:\projetos\speednetwork\venv\lib\site-packages\django\core\handlers\exception.py", line 34, in inner
    response = get_response(request)
  File "C:\projetos\speednetwork\venv\lib\site-packages\django\core\handlers\base.py", line 115, in _get_response
    response = self.process_exception_by_middleware(e, request)
  File "C:\projetos\speednetwork\venv\lib\site-packages\django\core\handlers\base.py", line 113, in _get_response
    response = wrapped_callback(request, *callback_args, **callback_kwargs)
TypeError: __init__() takes 1 positional argument but 2 were given
"GET /servicos/api/ HTTP/1.1" 500 72067
Internal Server Error: /cadastro-senhas-equipamentos/
Traceback (most recent call last):
  File "C:\projetos\speednetwork\venv\lib\site-packages\django\core\handlers\exception.py", line 34, in inner
    response = get_response(request)
  File "C:\projetos\speednetwork\venv\lib\site-packages\django\core\handlers\base.py", line 115, in _get_response
    response = self.process_exception_by_middleware(e, request)
  File "C:\projetos\speednetwork\venv\lib\site-packages\django\core\handlers\base.py", line 113, in _get_response
    response = wrapped_callback(request, *callback_args, **callback_kwargs)
  File "C:\projetos\speednetwork\apps\core\views.py", line 297, in CadastroSenhasPorEquipamentos
    return render(request, 'core/cadastro-senhas-equipamentos.html', {'form': form})
  File "C:\projetos\speednetwork\venv\lib\site-packages\django\shortcuts.py", line 19, in render
    content = loader.render_to_string(template_name, context, request, using=using)
  File "C:\projetos\speednetwork\venv\lib\site-packages\django\template\loader.py", line 61, in render_to_string
    template = get_template(template_name, using=using)
  File "C:\projetos\speednetwork\venv\lib\site-packages\django\template\loader.py", line 15, in get_template
    return engine.get_template(template_name)
  File "C:\projetos\speednetwork\venv\lib\site-packages\django\template\backends\django.py", line 34, in get_template
    return Template(self.engine.get_template(template_name), self)
  File "C:\projetos\speednetwork\venv\lib\site-packages\django\template\engine.py", line 143, in get_template
    template, origin = self.find_template(template_name)
  File "C:\projetos\speednetwork\venv\lib\site-packages\django\template\engine.py", line 125, in find_template
    template = loader.get_template(name, skip=skip)
  File "C:\projetos\speednetwork\venv\lib\site-packages\django\template\loaders\base.py", line 29, in get_template
    return Template(
  File "C:\projetos\speednetwork\venv\lib\site-packages\django\template\base.py", line 156, in __init__
    self.nodelist = self.compile_nodelist()
  File "C:\projetos\speednetwork\venv\lib\site-packages\django\template\base.py", line 194, in compile_nodelist
    return parser.parse()
  File "C:\projetos\speednetwork\venv\lib\site-packages\django\template\base.py", line 477, in parse
    raise self.error(token, e)
  File "C:\projetos\speednetwork\venv\lib\site-packages\django\template\base.py", line 475, in parse
    compiled_result = compile_func(self, token)
  File "C:\projetos\speednetwork\venv\lib\site-packages\django\template\loader_tags.py", line 266, in do_extends
    nodelist = parser.parse()
  File "C:\projetos\speednetwork\venv\lib\site-packages\django\template\base.py", line 477, in parse
    raise self.error(token, e)
  File "C:\projetos\speednetwork\venv\lib\site-packages\django\template\base.py", line 475, in parse
    compiled_result = compile_func(self, token)
  File "C:\projetos\speednetwork\venv\lib\site-packages\django\template\loader_tags.py", line 209, in do_block
    nodelist = parser.parse(('endblock',))
  File "C:\projetos\speednetwork\venv\lib\site-packages\django\template\base.py", line 448, in parse
    raise self.error(token, e)
  File "C:\projetos\speednetwork\venv\lib\site-packages\django\template\base.py", line 446, in parse
    filter_expression = self.compile_filter(token.contents)
  File "C:\projetos\speednetwork\venv\lib\site-packages\django\template\base.py", line 562, in compile_filter
    return FilterExpression(token, self)
  File "C:\projetos\speednetwork\venv\lib\site-packages\django\template\base.py", line 656, in __init__
    filter_func = parser.find_filter(filter_name)
  File "C:\projetos\speednetwork\venv\lib\site-packages\django\template\base.py", line 568, in find_filter
    raise TemplateSyntaxError("Invalid filter: '%s'" % filter_name)
django.template.exceptions.TemplateSyntaxError: Invalid filter: 'add_class'
"GET /cadastro-senhas-equipamentos/ HTTP/1.1" 500 177233
