admin Alterou uma cto: 13604/04/2022, 15:30:27
admin Alterou uma cto: ID:136 04/04/2022, 15:34:19
admin alterou a cto de ID:364 na data:  04/04/2022, 15:36:52
Internal Server Error: /admin/components/ruas/
Traceback (most recent call last):
  File "C:\projetos\speednetwork\venv\lib\site-packages\django\core\handlers\exception.py", line 34, in inner
    response = get_response(request)
  File "C:\projetos\speednetwork\venv\lib\site-packages\django\core\handlers\base.py", line 115, in _get_response
    response = self.process_exception_by_middleware(e, request)
  File "C:\projetos\speednetwork\venv\lib\site-packages\django\core\handlers\base.py", line 113, in _get_response
    response = wrapped_callback(request, *callback_args, **callback_kwargs)
  File "C:\projetos\speednetwork\venv\lib\site-packages\django\contrib\admin\options.py", line 607, in wrapper
    return self.admin_site.admin_view(view)(*args, **kwargs)
  File "C:\projetos\speednetwork\venv\lib\site-packages\django\utils\decorators.py", line 130, in _wrapped_view
    response = view_func(request, *args, **kwargs)
  File "C:\projetos\speednetwork\venv\lib\site-packages\django\views\decorators\cache.py", line 44, in _wrapped_view_func
    response = view_func(request, *args, **kwargs)
  File "C:\projetos\speednetwork\venv\lib\site-packages\django\contrib\admin\sites.py", line 231, in inner
    return view(request, *args, **kwargs)
  File "C:\projetos\speednetwork\venv\lib\site-packages\django\utils\decorators.py", line 43, in _wrapper
    return bound_method(*args, **kwargs)
  File "C:\projetos\speednetwork\venv\lib\site-packages\django\utils\decorators.py", line 130, in _wrapped_view
    response = view_func(request, *args, **kwargs)
  File "C:\projetos\speednetwork\venv\lib\site-packages\django\contrib\admin\options.py", line 1678, in changelist_view
    cl = self.get_changelist_instance(request)
  File "C:\projetos\speednetwork\venv\lib\site-packages\django\contrib\admin\options.py", line 728, in get_changelist_instance
    return ChangeList(
  File "C:\projetos\speednetwork\venv\lib\site-packages\django\contrib\admin\views\main.py", line 97, in __init__
    self.queryset = self.get_queryset(request)
  File "C:\projetos\speednetwork\venv\lib\site-packages\django\contrib\admin\views\main.py", line 457, in get_queryset
    qs, search_use_distinct = self.model_admin.get_search_results(request, qs, self.query)
  File "C:\projetos\speednetwork\venv\lib\site-packages\django\contrib\admin\options.py", line 1016, in get_search_results
    queryset = queryset.filter(reduce(operator.or_, or_queries))
  File "C:\projetos\speednetwork\venv\lib\site-packages\django\db\models\query.py", line 904, in filter
    return self._filter_or_exclude(False, *args, **kwargs)
  File "C:\projetos\speednetwork\venv\lib\site-packages\django\db\models\query.py", line 923, in _filter_or_exclude
    clone.query.add_q(Q(*args, **kwargs))
  File "C:\projetos\speednetwork\venv\lib\site-packages\django\db\models\sql\query.py", line 1337, in add_q
    clause, _ = self._add_q(q_object, self.used_aliases)
  File "C:\projetos\speednetwork\venv\lib\site-packages\django\db\models\sql\query.py", line 1357, in _add_q
    child_clause, needed_inner = self._add_q(
  File "C:\projetos\speednetwork\venv\lib\site-packages\django\db\models\sql\query.py", line 1362, in _add_q
    child_clause, needed_inner = self.build_filter(
  File "C:\projetos\speednetwork\venv\lib\site-packages\django\db\models\sql\query.py", line 1298, in build_filter
    condition = self.build_lookup(lookups, col, value)
  File "C:\projetos\speednetwork\venv\lib\site-packages\django\db\models\sql\query.py", line 1146, in build_lookup
    raise FieldError('Related Field got invalid lookup: {}'.format(lookup_name))
django.core.exceptions.FieldError: Related Field got invalid lookup: icontains
"GET /admin/components/ruas/?q=ar HTTP/1.1" 500 167421
Internal Server Error: /api/lista-servicos-api/
Traceback (most recent call last):
  File "C:\projetos\speednetwork\venv\lib\site-packages\django\core\handlers\exception.py", line 34, in inner
    response = get_response(request)
  File "C:\projetos\speednetwork\venv\lib\site-packages\django\core\handlers\base.py", line 115, in _get_response
    response = self.process_exception_by_middleware(e, request)
  File "C:\projetos\speednetwork\venv\lib\site-packages\django\core\handlers\base.py", line 113, in _get_response
    response = wrapped_callback(request, *callback_args, **callback_kwargs)
  File "C:\projetos\speednetwork\venv\lib\site-packages\django\views\decorators\csrf.py", line 54, in wrapped_view
    return view_func(*args, **kwargs)
  File "C:\projetos\speednetwork\venv\lib\site-packages\rest_framework\viewsets.py", line 125, in view
    return self.dispatch(request, *args, **kwargs)
  File "C:\projetos\speednetwork\venv\lib\site-packages\rest_framework\views.py", line 509, in dispatch
    response = self.handle_exception(exc)
  File "C:\projetos\speednetwork\venv\lib\site-packages\rest_framework\views.py", line 469, in handle_exception
    self.raise_uncaught_exception(exc)
  File "C:\projetos\speednetwork\venv\lib\site-packages\rest_framework\views.py", line 480, in raise_uncaught_exception
    raise exc
  File "C:\projetos\speednetwork\venv\lib\site-packages\rest_framework\views.py", line 506, in dispatch
    response = handler(request, *args, **kwargs)
  File "C:\projetos\speednetwork\venv\lib\site-packages\rest_framework\mixins.py", line 46, in list
    return Response(serializer.data)
  File "C:\projetos\speednetwork\venv\lib\site-packages\rest_framework\serializers.py", line 745, in data
    ret = super().data
  File "C:\projetos\speednetwork\venv\lib\site-packages\rest_framework\serializers.py", line 246, in data
    self._data = self.to_representation(self.instance)
  File "C:\projetos\speednetwork\venv\lib\site-packages\rest_framework\serializers.py", line 663, in to_representation
    return [
  File "C:\projetos\speednetwork\venv\lib\site-packages\rest_framework\serializers.py", line 664, in <listcomp>
    self.child.to_representation(item) for item in iterable
  File "C:\projetos\speednetwork\venv\lib\site-packages\rest_framework\serializers.py", line 500, in to_representation
    for field in fields:
  File "C:\projetos\speednetwork\venv\lib\site-packages\rest_framework\serializers.py", line 361, in _readable_fields
    for field in self.fields.values():
  File "C:\projetos\speednetwork\venv\lib\site-packages\django\utils\functional.py", line 48, in __get__
    res = instance.__dict__[self.name] = self.func(instance)
  File "C:\projetos\speednetwork\venv\lib\site-packages\rest_framework\serializers.py", line 349, in fields
    for key, value in self.get_fields().items():
  File "C:\projetos\speednetwork\venv\lib\site-packages\rest_framework\serializers.py", line 1029, in get_fields
    field_names = self.get_field_names(declared_fields, info)
  File "C:\projetos\speednetwork\venv\lib\site-packages\rest_framework\serializers.py", line 1125, in get_field_names
    assert field_name in fields, (
AssertionError: The field 'categoria' was declared on serializer ServicesSerializer, but has not been included in the 'fields' option.
"GET /api/lista-servicos-api/ HTTP/1.1" 500 157338
Internal Server Error: /api/lista-servicos-api/
Traceback (most recent call last):
  File "C:\projetos\speednetwork\venv\lib\site-packages\django\core\handlers\exception.py", line 34, in inner
    response = get_response(request)
  File "C:\projetos\speednetwork\venv\lib\site-packages\django\core\handlers\base.py", line 115, in _get_response
    response = self.process_exception_by_middleware(e, request)
  File "C:\projetos\speednetwork\venv\lib\site-packages\django\core\handlers\base.py", line 113, in _get_response
    response = wrapped_callback(request, *callback_args, **callback_kwargs)
  File "C:\projetos\speednetwork\venv\lib\site-packages\django\views\decorators\csrf.py", line 54, in wrapped_view
    return view_func(*args, **kwargs)
  File "C:\projetos\speednetwork\venv\lib\site-packages\rest_framework\viewsets.py", line 125, in view
    return self.dispatch(request, *args, **kwargs)
  File "C:\projetos\speednetwork\venv\lib\site-packages\rest_framework\views.py", line 509, in dispatch
    response = self.handle_exception(exc)
  File "C:\projetos\speednetwork\venv\lib\site-packages\rest_framework\views.py", line 469, in handle_exception
    self.raise_uncaught_exception(exc)
  File "C:\projetos\speednetwork\venv\lib\site-packages\rest_framework\views.py", line 480, in raise_uncaught_exception
    raise exc
  File "C:\projetos\speednetwork\venv\lib\site-packages\rest_framework\views.py", line 506, in dispatch
    response = handler(request, *args, **kwargs)
  File "C:\projetos\speednetwork\venv\lib\site-packages\rest_framework\mixins.py", line 46, in list
    return Response(serializer.data)
  File "C:\projetos\speednetwork\venv\lib\site-packages\rest_framework\serializers.py", line 745, in data
    ret = super().data
  File "C:\projetos\speednetwork\venv\lib\site-packages\rest_framework\serializers.py", line 246, in data
    self._data = self.to_representation(self.instance)
  File "C:\projetos\speednetwork\venv\lib\site-packages\rest_framework\serializers.py", line 663, in to_representation
    return [
  File "C:\projetos\speednetwork\venv\lib\site-packages\rest_framework\serializers.py", line 664, in <listcomp>
    self.child.to_representation(item) for item in iterable
  File "C:\projetos\speednetwork\venv\lib\site-packages\rest_framework\serializers.py", line 500, in to_representation
    for field in fields:
  File "C:\projetos\speednetwork\venv\lib\site-packages\rest_framework\serializers.py", line 361, in _readable_fields
    for field in self.fields.values():
  File "C:\projetos\speednetwork\venv\lib\site-packages\django\utils\functional.py", line 48, in __get__
    res = instance.__dict__[self.name] = self.func(instance)
  File "C:\projetos\speednetwork\venv\lib\site-packages\rest_framework\serializers.py", line 349, in fields
    for key, value in self.get_fields().items():
  File "C:\projetos\speednetwork\venv\lib\site-packages\rest_framework\serializers.py", line 1029, in get_fields
    field_names = self.get_field_names(declared_fields, info)
  File "C:\projetos\speednetwork\venv\lib\site-packages\rest_framework\serializers.py", line 1125, in get_field_names
    assert field_name in fields, (
AssertionError: The field 'categoria' was declared on serializer ServicesSerializer, but has not been included in the 'fields' option.
"GET /api/lista-servicos-api/ HTTP/1.1" 500 157338
Internal Server Error: /servicos/api/list-service
Traceback (most recent call last):
  File "C:\projetos\speednetwork\venv\lib\site-packages\django\db\backends\utils.py", line 86, in _execute
    return self.cursor.execute(sql, params)
  File "C:\projetos\speednetwork\venv\lib\site-packages\django\db\backends\sqlite3\base.py", line 396, in execute
    return Database.Cursor.execute(self, query, params)
sqlite3.IntegrityError: NOT NULL constraint failed: services_servico.categoria_id

The above exception was the direct cause of the following exception:

Traceback (most recent call last):
  File "C:\projetos\speednetwork\venv\lib\site-packages\django\core\handlers\exception.py", line 34, in inner
    response = get_response(request)
  File "C:\projetos\speednetwork\venv\lib\site-packages\django\core\handlers\base.py", line 115, in _get_response
    response = self.process_exception_by_middleware(e, request)
  File "C:\projetos\speednetwork\venv\lib\site-packages\django\core\handlers\base.py", line 113, in _get_response
    response = wrapped_callback(request, *callback_args, **callback_kwargs)
  File "C:\projetos\speednetwork\venv\lib\site-packages\django\views\decorators\csrf.py", line 54, in wrapped_view
    return view_func(*args, **kwargs)
  File "C:\projetos\speednetwork\venv\lib\site-packages\django\views\generic\base.py", line 71, in view
    return self.dispatch(request, *args, **kwargs)
  File "C:\projetos\speednetwork\venv\lib\site-packages\rest_framework\views.py", line 509, in dispatch
    response = self.handle_exception(exc)
  File "C:\projetos\speednetwork\venv\lib\site-packages\rest_framework\views.py", line 469, in handle_exception
    self.raise_uncaught_exception(exc)
  File "C:\projetos\speednetwork\venv\lib\site-packages\rest_framework\views.py", line 480, in raise_uncaught_exception
    raise exc
  File "C:\projetos\speednetwork\venv\lib\site-packages\rest_framework\views.py", line 506, in dispatch
    response = handler(request, *args, **kwargs)
  File "C:\projetos\speednetwork\venv\lib\site-packages\rest_framework\decorators.py", line 50, in handler
    return func(*args, **kwargs)
  File "C:\projetos\speednetwork\apps\services\api\viewsets.py", line 18, in service_list
    serializer.save()
  File "C:\projetos\speednetwork\venv\lib\site-packages\rest_framework\serializers.py", line 205, in save
    self.instance = self.create(validated_data)
  File "C:\projetos\speednetwork\venv\lib\site-packages\rest_framework\serializers.py", line 939, in create
    instance = ModelClass._default_manager.create(**validated_data)
  File "C:\projetos\speednetwork\venv\lib\site-packages\django\db\models\manager.py", line 82, in manager_method
    return getattr(self.get_queryset(), name)(*args, **kwargs)
  File "C:\projetos\speednetwork\venv\lib\site-packages\django\db\models\query.py", line 433, in create
    obj.save(force_insert=True, using=self.db)
  File "C:\projetos\speednetwork\venv\lib\site-packages\django\db\models\base.py", line 745, in save
    self.save_base(using=using, force_insert=force_insert,
  File "C:\projetos\speednetwork\venv\lib\site-packages\django\db\models\base.py", line 782, in save_base
    updated = self._save_table(
  File "C:\projetos\speednetwork\venv\lib\site-packages\django\db\models\base.py", line 886, in _save_table
    results = self._do_insert(cls._base_manager, using, fields, returning_fields, raw)
  File "C:\projetos\speednetwork\venv\lib\site-packages\django\db\models\base.py", line 923, in _do_insert
    return manager._insert(
  File "C:\projetos\speednetwork\venv\lib\site-packages\django\db\models\manager.py", line 82, in manager_method
    return getattr(self.get_queryset(), name)(*args, **kwargs)
  File "C:\projetos\speednetwork\venv\lib\site-packages\django\db\models\query.py", line 1204, in _insert
    return query.get_compiler(using=using).execute_sql(returning_fields)
  File "C:\projetos\speednetwork\venv\lib\site-packages\django\db\models\sql\compiler.py", line 1377, in execute_sql
    cursor.execute(sql, params)
  File "C:\projetos\speednetwork\venv\lib\site-packages\django\db\backends\utils.py", line 100, in execute
    return super().execute(sql, params)
  File "C:\projetos\speednetwork\venv\lib\site-packages\django\db\backends\utils.py", line 68, in execute
    return self._execute_with_wrappers(sql, params, many=False, executor=self._execute)
  File "C:\projetos\speednetwork\venv\lib\site-packages\django\db\backends\utils.py", line 77, in _execute_with_wrappers
    return executor(sql, params, many, context)
  File "C:\projetos\speednetwork\venv\lib\site-packages\django\db\backends\utils.py", line 86, in _execute
    return self.cursor.execute(sql, params)
  File "C:\projetos\speednetwork\venv\lib\site-packages\django\db\utils.py", line 90, in __exit__
    raise dj_exc_value.with_traceback(traceback) from exc_value
  File "C:\projetos\speednetwork\venv\lib\site-packages\django\db\backends\utils.py", line 86, in _execute
    return self.cursor.execute(sql, params)
  File "C:\projetos\speednetwork\venv\lib\site-packages\django\db\backends\sqlite3\base.py", line 396, in execute
    return Database.Cursor.execute(self, query, params)
django.db.utils.IntegrityError: NOT NULL constraint failed: services_servico.categoria_id
"POST /servicos/api/list-service HTTP/1.1" 500 223474
Internal Server Error: /servicos/api/
Traceback (most recent call last):
  File "C:\projetos\speednetwork\venv\lib\site-packages\django\core\handlers\exception.py", line 34, in inner
    response = get_response(request)
  File "C:\projetos\speednetwork\venv\lib\site-packages\django\core\handlers\base.py", line 115, in _get_response
    response = self.process_exception_by_middleware(e, request)
  File "C:\projetos\speednetwork\venv\lib\site-packages\django\core\handlers\base.py", line 113, in _get_response
    response = wrapped_callback(request, *callback_args, **callback_kwargs)
TypeError: __init__() takes 1 positional argument but 2 were given
"GET /servicos/api/ HTTP/1.1" 500 72067
Internal Server Error: /cadastro-senhas-equipamentos/
Traceback (most recent call last):
  File "C:\projetos\speednetwork\venv\lib\site-packages\django\core\handlers\exception.py", line 34, in inner
    response = get_response(request)
  File "C:\projetos\speednetwork\venv\lib\site-packages\django\core\handlers\base.py", line 115, in _get_response
    response = self.process_exception_by_middleware(e, request)
  File "C:\projetos\speednetwork\venv\lib\site-packages\django\core\handlers\base.py", line 113, in _get_response
    response = wrapped_callback(request, *callback_args, **callback_kwargs)
  File "C:\projetos\speednetwork\apps\core\views.py", line 297, in CadastroSenhasPorEquipamentos
    return render(request, 'core/cadastro-senhas-equipamentos.html', {'form': form})
  File "C:\projetos\speednetwork\venv\lib\site-packages\django\shortcuts.py", line 19, in render
    content = loader.render_to_string(template_name, context, request, using=using)
  File "C:\projetos\speednetwork\venv\lib\site-packages\django\template\loader.py", line 61, in render_to_string
    template = get_template(template_name, using=using)
  File "C:\projetos\speednetwork\venv\lib\site-packages\django\template\loader.py", line 15, in get_template
    return engine.get_template(template_name)
  File "C:\projetos\speednetwork\venv\lib\site-packages\django\template\backends\django.py", line 34, in get_template
    return Template(self.engine.get_template(template_name), self)
  File "C:\projetos\speednetwork\venv\lib\site-packages\django\template\engine.py", line 143, in get_template
    template, origin = self.find_template(template_name)
  File "C:\projetos\speednetwork\venv\lib\site-packages\django\template\engine.py", line 125, in find_template
    template = loader.get_template(name, skip=skip)
  File "C:\projetos\speednetwork\venv\lib\site-packages\django\template\loaders\base.py", line 29, in get_template
    return Template(
  File "C:\projetos\speednetwork\venv\lib\site-packages\django\template\base.py", line 156, in __init__
    self.nodelist = self.compile_nodelist()
  File "C:\projetos\speednetwork\venv\lib\site-packages\django\template\base.py", line 194, in compile_nodelist
    return parser.parse()
  File "C:\projetos\speednetwork\venv\lib\site-packages\django\template\base.py", line 477, in parse
    raise self.error(token, e)
  File "C:\projetos\speednetwork\venv\lib\site-packages\django\template\base.py", line 475, in parse
    compiled_result = compile_func(self, token)
  File "C:\projetos\speednetwork\venv\lib\site-packages\django\template\loader_tags.py", line 266, in do_extends
    nodelist = parser.parse()
  File "C:\projetos\speednetwork\venv\lib\site-packages\django\template\base.py", line 477, in parse
    raise self.error(token, e)
  File "C:\projetos\speednetwork\venv\lib\site-packages\django\template\base.py", line 475, in parse
    compiled_result = compile_func(self, token)
  File "C:\projetos\speednetwork\venv\lib\site-packages\django\template\loader_tags.py", line 209, in do_block
    nodelist = parser.parse(('endblock',))
  File "C:\projetos\speednetwork\venv\lib\site-packages\django\template\base.py", line 448, in parse
    raise self.error(token, e)
  File "C:\projetos\speednetwork\venv\lib\site-packages\django\template\base.py", line 446, in parse
    filter_expression = self.compile_filter(token.contents)
  File "C:\projetos\speednetwork\venv\lib\site-packages\django\template\base.py", line 562, in compile_filter
    return FilterExpression(token, self)
  File "C:\projetos\speednetwork\venv\lib\site-packages\django\template\base.py", line 656, in __init__
    filter_func = parser.find_filter(filter_name)
  File "C:\projetos\speednetwork\venv\lib\site-packages\django\template\base.py", line 568, in find_filter
    raise TemplateSyntaxError("Invalid filter: '%s'" % filter_name)
django.template.exceptions.TemplateSyntaxError: Invalid filter: 'add_class'
"GET /cadastro-senhas-equipamentos/ HTTP/1.1" 500 177233
Internal Server Error: /pagamentos/editar-pagamento-agendado/46
Traceback (most recent call last):
  File "C:\projetos\speednetwork\venv\lib\site-packages\django\core\handlers\exception.py", line 34, in inner
    response = get_response(request)
  File "C:\projetos\speednetwork\venv\lib\site-packages\django\core\handlers\base.py", line 115, in _get_response
    response = self.process_exception_by_middleware(e, request)
  File "C:\projetos\speednetwork\venv\lib\site-packages\django\core\handlers\base.py", line 113, in _get_response
    response = wrapped_callback(request, *callback_args, **callback_kwargs)
  File "C:\projetos\speednetwork\venv\lib\site-packages\django\views\generic\base.py", line 71, in view
    return self.dispatch(request, *args, **kwargs)
  File "C:\projetos\speednetwork\venv\lib\site-packages\django\views\generic\base.py", line 97, in dispatch
    return handler(request, *args, **kwargs)
  File "C:\projetos\speednetwork\venv\lib\site-packages\django\views\generic\edit.py", line 190, in get
    return super().get(request, *args, **kwargs)
  File "C:\projetos\speednetwork\venv\lib\site-packages\django\views\generic\edit.py", line 133, in get
    return self.render_to_response(self.get_context_data())
  File "C:\projetos\speednetwork\venv\lib\site-packages\django\views\generic\edit.py", line 66, in get_context_data
    kwargs['form'] = self.get_form()
  File "C:\projetos\speednetwork\venv\lib\site-packages\django\views\generic\edit.py", line 32, in get_form
    form_class = self.get_form_class()
  File "C:\projetos\speednetwork\venv\lib\site-packages\django\views\generic\edit.py", line 77, in get_form_class
    raise ImproperlyConfigured(
django.core.exceptions.ImproperlyConfigured: Specifying both 'fields' and 'form_class' is not permitted.
"GET /pagamentos/editar-pagamento-agendado/46 HTTP/1.1" 500 100737
Internal Server Error: /pagamentos/lista-pagamentos/
Traceback (most recent call last):
  File "C:\projetos\speednetwork\venv\lib\site-packages\django\core\handlers\exception.py", line 34, in inner
    response = get_response(request)
  File "C:\projetos\speednetwork\venv\lib\site-packages\django\core\handlers\base.py", line 115, in _get_response
    response = self.process_exception_by_middleware(e, request)
  File "C:\projetos\speednetwork\venv\lib\site-packages\django\core\handlers\base.py", line 113, in _get_response
    response = wrapped_callback(request, *callback_args, **callback_kwargs)
  File "C:\projetos\speednetwork\apps\payment\views.py", line 489, in ListaPagamentos
    return render(request, 'payment/lista_pagamentos.html', context)
  File "C:\projetos\speednetwork\venv\lib\site-packages\django\shortcuts.py", line 19, in render
    content = loader.render_to_string(template_name, context, request, using=using)
  File "C:\projetos\speednetwork\venv\lib\site-packages\django\template\loader.py", line 62, in render_to_string
    return template.render(context, request)
  File "C:\projetos\speednetwork\venv\lib\site-packages\django\template\backends\django.py", line 61, in render
    return self.template.render(context)
  File "C:\projetos\speednetwork\venv\lib\site-packages\django\template\base.py", line 171, in render
    return self._render(context)
  File "C:\projetos\speednetwork\venv\lib\site-packages\django\template\base.py", line 163, in _render
    return self.nodelist.render(context)
  File "C:\projetos\speednetwork\venv\lib\site-packages\django\template\base.py", line 936, in render
    bit = node.render_annotated(context)
  File "C:\projetos\speednetwork\venv\lib\site-packages\django\template\base.py", line 903, in render_annotated
    return self.render(context)
  File "C:\projetos\speednetwork\venv\lib\site-packages\django\template\loader_tags.py", line 150, in render
    return compiled_parent._render(context)
  File "C:\projetos\speednetwork\venv\lib\site-packages\django\template\base.py", line 163, in _render
    return self.nodelist.render(context)
  File "C:\projetos\speednetwork\venv\lib\site-packages\django\template\base.py", line 936, in render
    bit = node.render_annotated(context)
  File "C:\projetos\speednetwork\venv\lib\site-packages\django\template\base.py", line 903, in render_annotated
    return self.render(context)
  File "C:\projetos\speednetwork\venv\lib\site-packages\django\template\loader_tags.py", line 62, in render
    result = block.nodelist.render(context)
  File "C:\projetos\speednetwork\venv\lib\site-packages\django\template\base.py", line 936, in render
    bit = node.render_annotated(context)
  File "C:\projetos\speednetwork\venv\lib\site-packages\django\template\base.py", line 903, in render_annotated
    return self.render(context)
  File "C:\projetos\speednetwork\venv\lib\site-packages\django\template\defaulttags.py", line 209, in render
    nodelist.append(node.render_annotated(context))
  File "C:\projetos\speednetwork\venv\lib\site-packages\django\template\base.py", line 903, in render_annotated
    return self.render(context)
  File "C:\projetos\speednetwork\venv\lib\site-packages\django\template\defaulttags.py", line 443, in render
    url = reverse(view_name, args=args, kwargs=kwargs, current_app=current_app)
  File "C:\projetos\speednetwork\venv\lib\site-packages\django\urls\base.py", line 87, in reverse
    return iri_to_uri(resolver._reverse_with_prefix(view, prefix, *args, **kwargs))
  File "C:\projetos\speednetwork\venv\lib\site-packages\django\urls\resolvers.py", line 676, in _reverse_with_prefix
    raise NoReverseMatch(msg)
django.urls.exceptions.NoReverseMatch: Reverse for 'editar_pagamento_agendado' with arguments '('',)' not found. 1 pattern(s) tried: ['pagamentos/editar\\-pagamento\\-agendado/(?P<pk>[0-9]+)$']
"GET /pagamentos/lista-pagamentos/ HTTP/1.1" 500 191643
Internal Server Error: /pagamentos/lista-pagamentos/
Traceback (most recent call last):
  File "C:\projetos\speednetwork\venv\lib\site-packages\django\core\handlers\exception.py", line 34, in inner
    response = get_response(request)
  File "C:\projetos\speednetwork\venv\lib\site-packages\django\core\handlers\base.py", line 115, in _get_response
    response = self.process_exception_by_middleware(e, request)
  File "C:\projetos\speednetwork\venv\lib\site-packages\django\core\handlers\base.py", line 113, in _get_response
    response = wrapped_callback(request, *callback_args, **callback_kwargs)
  File "C:\projetos\speednetwork\apps\payment\views.py", line 489, in ListaPagamentos
    return render(request, 'payment/atualizar-pagamento.html', context)
  File "C:\projetos\speednetwork\venv\lib\site-packages\django\shortcuts.py", line 19, in render
    content = loader.render_to_string(template_name, context, request, using=using)
  File "C:\projetos\speednetwork\venv\lib\site-packages\django\template\loader.py", line 62, in render_to_string
    return template.render(context, request)
  File "C:\projetos\speednetwork\venv\lib\site-packages\django\template\backends\django.py", line 61, in render
    return self.template.render(context)
  File "C:\projetos\speednetwork\venv\lib\site-packages\django\template\base.py", line 171, in render
    return self._render(context)
  File "C:\projetos\speednetwork\venv\lib\site-packages\django\template\base.py", line 163, in _render
    return self.nodelist.render(context)
  File "C:\projetos\speednetwork\venv\lib\site-packages\django\template\base.py", line 936, in render
    bit = node.render_annotated(context)
  File "C:\projetos\speednetwork\venv\lib\site-packages\django\template\base.py", line 903, in render_annotated
    return self.render(context)
  File "C:\projetos\speednetwork\venv\lib\site-packages\django\template\loader_tags.py", line 150, in render
    return compiled_parent._render(context)
  File "C:\projetos\speednetwork\venv\lib\site-packages\django\template\base.py", line 163, in _render
    return self.nodelist.render(context)
  File "C:\projetos\speednetwork\venv\lib\site-packages\django\template\base.py", line 936, in render
    bit = node.render_annotated(context)
  File "C:\projetos\speednetwork\venv\lib\site-packages\django\template\base.py", line 903, in render_annotated
    return self.render(context)
  File "C:\projetos\speednetwork\venv\lib\site-packages\django\template\loader_tags.py", line 62, in render
    result = block.nodelist.render(context)
  File "C:\projetos\speednetwork\venv\lib\site-packages\django\template\base.py", line 936, in render
    bit = node.render_annotated(context)
  File "C:\projetos\speednetwork\venv\lib\site-packages\django\template\base.py", line 903, in render_annotated
    return self.render(context)
  File "C:\projetos\speednetwork\venv\lib\site-packages\django\template\base.py", line 986, in render
    output = self.filter_expression.resolve(context)
  File "C:\projetos\speednetwork\venv\lib\site-packages\django\template\base.py", line 697, in resolve
    new_obj = func(obj, *arg_vals)
  File "C:\projetos\speednetwork\venv\lib\site-packages\crispy_forms\templatetags\crispy_forms_filters.py", line 102, in as_crispy_field
    raise CrispyError("|as_crispy_field got passed an invalid or inexistent field")
crispy_forms.exceptions.CrispyError: |as_crispy_field got passed an invalid or inexistent field
"GET /pagamentos/lista-pagamentos/ HTTP/1.1" 500 164739
Internal Server Error: /pagamentos/lista-pagamentos/
Traceback (most recent call last):
  File "C:\projetos\speednetwork\venv\lib\site-packages\django\core\handlers\exception.py", line 34, in inner
    response = get_response(request)
  File "C:\projetos\speednetwork\venv\lib\site-packages\django\core\handlers\base.py", line 115, in _get_response
    response = self.process_exception_by_middleware(e, request)
  File "C:\projetos\speednetwork\venv\lib\site-packages\django\core\handlers\base.py", line 113, in _get_response
    response = wrapped_callback(request, *callback_args, **callback_kwargs)
  File "C:\projetos\speednetwork\apps\payment\views.py", line 489, in ListaPagamentos
    return render(request, 'payment/atualizar-pagamento.html', context)
  File "C:\projetos\speednetwork\venv\lib\site-packages\django\shortcuts.py", line 19, in render
    content = loader.render_to_string(template_name, context, request, using=using)
  File "C:\projetos\speednetwork\venv\lib\site-packages\django\template\loader.py", line 62, in render_to_string
    return template.render(context, request)
  File "C:\projetos\speednetwork\venv\lib\site-packages\django\template\backends\django.py", line 61, in render
    return self.template.render(context)
  File "C:\projetos\speednetwork\venv\lib\site-packages\django\template\base.py", line 171, in render
    return self._render(context)
  File "C:\projetos\speednetwork\venv\lib\site-packages\django\template\base.py", line 163, in _render
    return self.nodelist.render(context)
  File "C:\projetos\speednetwork\venv\lib\site-packages\django\template\base.py", line 936, in render
    bit = node.render_annotated(context)
  File "C:\projetos\speednetwork\venv\lib\site-packages\django\template\base.py", line 903, in render_annotated
    return self.render(context)
  File "C:\projetos\speednetwork\venv\lib\site-packages\django\template\loader_tags.py", line 150, in render
    return compiled_parent._render(context)
  File "C:\projetos\speednetwork\venv\lib\site-packages\django\template\base.py", line 163, in _render
    return self.nodelist.render(context)
  File "C:\projetos\speednetwork\venv\lib\site-packages\django\template\base.py", line 936, in render
    bit = node.render_annotated(context)
  File "C:\projetos\speednetwork\venv\lib\site-packages\django\template\base.py", line 903, in render_annotated
    return self.render(context)
  File "C:\projetos\speednetwork\venv\lib\site-packages\django\template\loader_tags.py", line 62, in render
    result = block.nodelist.render(context)
  File "C:\projetos\speednetwork\venv\lib\site-packages\django\template\base.py", line 936, in render
    bit = node.render_annotated(context)
  File "C:\projetos\speednetwork\venv\lib\site-packages\django\template\base.py", line 903, in render_annotated
    return self.render(context)
  File "C:\projetos\speednetwork\venv\lib\site-packages\django\template\base.py", line 986, in render
    output = self.filter_expression.resolve(context)
  File "C:\projetos\speednetwork\venv\lib\site-packages\django\template\base.py", line 697, in resolve
    new_obj = func(obj, *arg_vals)
  File "C:\projetos\speednetwork\venv\lib\site-packages\crispy_forms\templatetags\crispy_forms_filters.py", line 102, in as_crispy_field
    raise CrispyError("|as_crispy_field got passed an invalid or inexistent field")
crispy_forms.exceptions.CrispyError: |as_crispy_field got passed an invalid or inexistent field
"GET /pagamentos/lista-pagamentos/ HTTP/1.1" 500 164738
Internal Server Error: /pagamentos/lista-pagamentos/
Traceback (most recent call last):
  File "C:\projetos\speednetwork\venv\lib\site-packages\django\core\handlers\exception.py", line 34, in inner
    response = get_response(request)
  File "C:\projetos\speednetwork\venv\lib\site-packages\django\core\handlers\base.py", line 115, in _get_response
    response = self.process_exception_by_middleware(e, request)
  File "C:\projetos\speednetwork\venv\lib\site-packages\django\core\handlers\base.py", line 113, in _get_response
    response = wrapped_callback(request, *callback_args, **callback_kwargs)
  File "C:\projetos\speednetwork\apps\payment\views.py", line 489, in ListaPagamentos
    return render(request, 'payment/lista_pagamentos.html', context)
  File "C:\projetos\speednetwork\venv\lib\site-packages\django\shortcuts.py", line 19, in render
    content = loader.render_to_string(template_name, context, request, using=using)
  File "C:\projetos\speednetwork\venv\lib\site-packages\django\template\loader.py", line 62, in render_to_string
    return template.render(context, request)
  File "C:\projetos\speednetwork\venv\lib\site-packages\django\template\backends\django.py", line 61, in render
    return self.template.render(context)
  File "C:\projetos\speednetwork\venv\lib\site-packages\django\template\base.py", line 171, in render
    return self._render(context)
  File "C:\projetos\speednetwork\venv\lib\site-packages\django\template\base.py", line 163, in _render
    return self.nodelist.render(context)
  File "C:\projetos\speednetwork\venv\lib\site-packages\django\template\base.py", line 936, in render
    bit = node.render_annotated(context)
  File "C:\projetos\speednetwork\venv\lib\site-packages\django\template\base.py", line 903, in render_annotated
    return self.render(context)
  File "C:\projetos\speednetwork\venv\lib\site-packages\django\template\loader_tags.py", line 150, in render
    return compiled_parent._render(context)
  File "C:\projetos\speednetwork\venv\lib\site-packages\django\template\base.py", line 163, in _render
    return self.nodelist.render(context)
  File "C:\projetos\speednetwork\venv\lib\site-packages\django\template\base.py", line 936, in render
    bit = node.render_annotated(context)
  File "C:\projetos\speednetwork\venv\lib\site-packages\django\template\base.py", line 903, in render_annotated
    return self.render(context)
  File "C:\projetos\speednetwork\venv\lib\site-packages\django\template\loader_tags.py", line 62, in render
    result = block.nodelist.render(context)
  File "C:\projetos\speednetwork\venv\lib\site-packages\django\template\base.py", line 936, in render
    bit = node.render_annotated(context)
  File "C:\projetos\speednetwork\venv\lib\site-packages\django\template\base.py", line 903, in render_annotated
    return self.render(context)
  File "C:\projetos\speednetwork\venv\lib\site-packages\django\template\defaulttags.py", line 209, in render
    nodelist.append(node.render_annotated(context))
  File "C:\projetos\speednetwork\venv\lib\site-packages\django\template\base.py", line 903, in render_annotated
    return self.render(context)
  File "C:\projetos\speednetwork\venv\lib\site-packages\django\template\defaulttags.py", line 443, in render
    url = reverse(view_name, args=args, kwargs=kwargs, current_app=current_app)
  File "C:\projetos\speednetwork\venv\lib\site-packages\django\urls\base.py", line 87, in reverse
    return iri_to_uri(resolver._reverse_with_prefix(view, prefix, *args, **kwargs))
  File "C:\projetos\speednetwork\venv\lib\site-packages\django\urls\resolvers.py", line 676, in _reverse_with_prefix
    raise NoReverseMatch(msg)
django.urls.exceptions.NoReverseMatch: Reverse for 'editar_pagamento_agendado' with arguments '('',)' not found. 1 pattern(s) tried: ['pagamentos/editar\\-pagamento\\-agendado/(?P<pk>[0-9]+)$']
"GET /pagamentos/lista-pagamentos/ HTTP/1.1" 500 191779
Internal Server Error: /pagamentos/lista-pagamentos/
Traceback (most recent call last):
  File "C:\projetos\speednetwork\venv\lib\site-packages\django\core\handlers\exception.py", line 34, in inner
    response = get_response(request)
  File "C:\projetos\speednetwork\venv\lib\site-packages\django\core\handlers\base.py", line 115, in _get_response
    response = self.process_exception_by_middleware(e, request)
  File "C:\projetos\speednetwork\venv\lib\site-packages\django\core\handlers\base.py", line 113, in _get_response
    response = wrapped_callback(request, *callback_args, **callback_kwargs)
  File "C:\projetos\speednetwork\apps\payment\views.py", line 489, in ListaPagamentos
    return render(request, 'payment/lista_pagamentos.html', context)
  File "C:\projetos\speednetwork\venv\lib\site-packages\django\shortcuts.py", line 19, in render
    content = loader.render_to_string(template_name, context, request, using=using)
  File "C:\projetos\speednetwork\venv\lib\site-packages\django\template\loader.py", line 62, in render_to_string
    return template.render(context, request)
  File "C:\projetos\speednetwork\venv\lib\site-packages\django\template\backends\django.py", line 61, in render
    return self.template.render(context)
  File "C:\projetos\speednetwork\venv\lib\site-packages\django\template\base.py", line 171, in render
    return self._render(context)
  File "C:\projetos\speednetwork\venv\lib\site-packages\django\template\base.py", line 163, in _render
    return self.nodelist.render(context)
  File "C:\projetos\speednetwork\venv\lib\site-packages\django\template\base.py", line 936, in render
    bit = node.render_annotated(context)
  File "C:\projetos\speednetwork\venv\lib\site-packages\django\template\base.py", line 903, in render_annotated
    return self.render(context)
  File "C:\projetos\speednetwork\venv\lib\site-packages\django\template\loader_tags.py", line 150, in render
    return compiled_parent._render(context)
  File "C:\projetos\speednetwork\venv\lib\site-packages\django\template\base.py", line 163, in _render
    return self.nodelist.render(context)
  File "C:\projetos\speednetwork\venv\lib\site-packages\django\template\base.py", line 936, in render
    bit = node.render_annotated(context)
  File "C:\projetos\speednetwork\venv\lib\site-packages\django\template\base.py", line 903, in render_annotated
    return self.render(context)
  File "C:\projetos\speednetwork\venv\lib\site-packages\django\template\loader_tags.py", line 62, in render
    result = block.nodelist.render(context)
  File "C:\projetos\speednetwork\venv\lib\site-packages\django\template\base.py", line 936, in render
    bit = node.render_annotated(context)
  File "C:\projetos\speednetwork\venv\lib\site-packages\django\template\base.py", line 903, in render_annotated
    return self.render(context)
  File "C:\projetos\speednetwork\venv\lib\site-packages\django\template\defaulttags.py", line 209, in render
    nodelist.append(node.render_annotated(context))
  File "C:\projetos\speednetwork\venv\lib\site-packages\django\template\base.py", line 903, in render_annotated
    return self.render(context)
  File "C:\projetos\speednetwork\venv\lib\site-packages\django\template\defaulttags.py", line 443, in render
    url = reverse(view_name, args=args, kwargs=kwargs, current_app=current_app)
  File "C:\projetos\speednetwork\venv\lib\site-packages\django\urls\base.py", line 87, in reverse
    return iri_to_uri(resolver._reverse_with_prefix(view, prefix, *args, **kwargs))
  File "C:\projetos\speednetwork\venv\lib\site-packages\django\urls\resolvers.py", line 676, in _reverse_with_prefix
    raise NoReverseMatch(msg)
django.urls.exceptions.NoReverseMatch: Reverse for 'editar_pagamento_agendado' with arguments '('',)' not found. 1 pattern(s) tried: ['pagamentos/editar\\-pagamento\\-agendado/(?P<pk>[0-9]+)$']
"GET /pagamentos/lista-pagamentos/ HTTP/1.1" 500 191642
Internal Server Error: /pagamentos/lista-pagamentos/
Traceback (most recent call last):
  File "C:\projetos\speednetwork\venv\lib\site-packages\django\core\handlers\exception.py", line 34, in inner
    response = get_response(request)
  File "C:\projetos\speednetwork\venv\lib\site-packages\django\core\handlers\base.py", line 115, in _get_response
    response = self.process_exception_by_middleware(e, request)
  File "C:\projetos\speednetwork\venv\lib\site-packages\django\core\handlers\base.py", line 113, in _get_response
    response = wrapped_callback(request, *callback_args, **callback_kwargs)
  File "C:\projetos\speednetwork\apps\payment\views.py", line 489, in ListaPagamentos
    return render(request, 'payment/lista_pagamentos.html', context)
  File "C:\projetos\speednetwork\venv\lib\site-packages\django\shortcuts.py", line 19, in render
    content = loader.render_to_string(template_name, context, request, using=using)
  File "C:\projetos\speednetwork\venv\lib\site-packages\django\template\loader.py", line 62, in render_to_string
    return template.render(context, request)
  File "C:\projetos\speednetwork\venv\lib\site-packages\django\template\backends\django.py", line 61, in render
    return self.template.render(context)
  File "C:\projetos\speednetwork\venv\lib\site-packages\django\template\base.py", line 171, in render
    return self._render(context)
  File "C:\projetos\speednetwork\venv\lib\site-packages\django\template\base.py", line 163, in _render
    return self.nodelist.render(context)
  File "C:\projetos\speednetwork\venv\lib\site-packages\django\template\base.py", line 936, in render
    bit = node.render_annotated(context)
  File "C:\projetos\speednetwork\venv\lib\site-packages\django\template\base.py", line 903, in render_annotated
    return self.render(context)
  File "C:\projetos\speednetwork\venv\lib\site-packages\django\template\loader_tags.py", line 150, in render
    return compiled_parent._render(context)
  File "C:\projetos\speednetwork\venv\lib\site-packages\django\template\base.py", line 163, in _render
    return self.nodelist.render(context)
  File "C:\projetos\speednetwork\venv\lib\site-packages\django\template\base.py", line 936, in render
    bit = node.render_annotated(context)
  File "C:\projetos\speednetwork\venv\lib\site-packages\django\template\base.py", line 903, in render_annotated
    return self.render(context)
  File "C:\projetos\speednetwork\venv\lib\site-packages\django\template\loader_tags.py", line 62, in render
    result = block.nodelist.render(context)
  File "C:\projetos\speednetwork\venv\lib\site-packages\django\template\base.py", line 936, in render
    bit = node.render_annotated(context)
  File "C:\projetos\speednetwork\venv\lib\site-packages\django\template\base.py", line 903, in render_annotated
    return self.render(context)
  File "C:\projetos\speednetwork\venv\lib\site-packages\django\template\defaulttags.py", line 209, in render
    nodelist.append(node.render_annotated(context))
  File "C:\projetos\speednetwork\venv\lib\site-packages\django\template\base.py", line 903, in render_annotated
    return self.render(context)
  File "C:\projetos\speednetwork\venv\lib\site-packages\django\template\defaulttags.py", line 443, in render
    url = reverse(view_name, args=args, kwargs=kwargs, current_app=current_app)
  File "C:\projetos\speednetwork\venv\lib\site-packages\django\urls\base.py", line 87, in reverse
    return iri_to_uri(resolver._reverse_with_prefix(view, prefix, *args, **kwargs))
  File "C:\projetos\speednetwork\venv\lib\site-packages\django\urls\resolvers.py", line 676, in _reverse_with_prefix
    raise NoReverseMatch(msg)
django.urls.exceptions.NoReverseMatch: Reverse for 'editar_pagamento_agendado' with arguments '('',)' not found. 1 pattern(s) tried: ['pagamentos/editar\\-pagamento\\-agendado/(?P<pk>[0-9]+)$']
"GET /pagamentos/lista-pagamentos/ HTTP/1.1" 500 191779
Internal Server Error: /servicos/servicos-abertos/
Traceback (most recent call last):
  File "C:\projetos\speednetwork\venv\lib\site-packages\django\template\backends\django.py", line 61, in render
    return self.template.render(context)
  File "C:\projetos\speednetwork\venv\lib\site-packages\django\template\base.py", line 171, in render
    return self._render(context)
  File "C:\projetos\speednetwork\venv\lib\site-packages\django\template\base.py", line 163, in _render
    return self.nodelist.render(context)
  File "C:\projetos\speednetwork\venv\lib\site-packages\django\template\base.py", line 936, in render
    bit = node.render_annotated(context)
  File "C:\projetos\speednetwork\venv\lib\site-packages\django\template\base.py", line 903, in render_annotated
    return self.render(context)
  File "C:\projetos\speednetwork\venv\lib\site-packages\django\template\loader_tags.py", line 150, in render
    return compiled_parent._render(context)
  File "C:\projetos\speednetwork\venv\lib\site-packages\django\template\base.py", line 163, in _render
    return self.nodelist.render(context)
  File "C:\projetos\speednetwork\venv\lib\site-packages\django\template\base.py", line 936, in render
    bit = node.render_annotated(context)
  File "C:\projetos\speednetwork\venv\lib\site-packages\django\template\base.py", line 903, in render_annotated
    return self.render(context)
  File "C:\projetos\speednetwork\venv\lib\site-packages\django\template\loader_tags.py", line 62, in render
    result = block.nodelist.render(context)
  File "C:\projetos\speednetwork\venv\lib\site-packages\django\template\base.py", line 936, in render
    bit = node.render_annotated(context)
  File "C:\projetos\speednetwork\venv\lib\site-packages\django\template\base.py", line 903, in render_annotated
    return self.render(context)
  File "C:\projetos\speednetwork\venv\lib\site-packages\django\template\loader_tags.py", line 176, in render
    template = context.template.engine.get_template(template_name)
  File "C:\projetos\speednetwork\venv\lib\site-packages\django\template\engine.py", line 143, in get_template
    template, origin = self.find_template(template_name)
  File "C:\projetos\speednetwork\venv\lib\site-packages\django\template\engine.py", line 129, in find_template
    raise TemplateDoesNotExist(name, tried=tried)
django.template.exceptions.TemplateDoesNotExist: agendar-servico.html

The above exception was the direct cause of the following exception:

Traceback (most recent call last):
  File "C:\projetos\speednetwork\venv\lib\site-packages\django\core\handlers\exception.py", line 34, in inner
    response = get_response(request)
  File "C:\projetos\speednetwork\venv\lib\site-packages\django\core\handlers\base.py", line 115, in _get_response
    response = self.process_exception_by_middleware(e, request)
  File "C:\projetos\speednetwork\venv\lib\site-packages\django\core\handlers\base.py", line 113, in _get_response
    response = wrapped_callback(request, *callback_args, **callback_kwargs)
  File "C:\projetos\speednetwork\apps\services\views.py", line 156, in ServicosAbertos
    return render(request, 'services/servicos-abertos.html', context)
  File "C:\projetos\speednetwork\venv\lib\site-packages\django\shortcuts.py", line 19, in render
    content = loader.render_to_string(template_name, context, request, using=using)
  File "C:\projetos\speednetwork\venv\lib\site-packages\django\template\loader.py", line 62, in render_to_string
    return template.render(context, request)
  File "C:\projetos\speednetwork\venv\lib\site-packages\django\template\backends\django.py", line 63, in render
    reraise(exc, self.backend)
  File "C:\projetos\speednetwork\venv\lib\site-packages\django\template\backends\django.py", line 84, in reraise
    raise new from exc
django.template.exceptions.TemplateDoesNotExist: agendar-servico.html
"GET /servicos/servicos-abertos/ HTTP/1.1" 500 183162
Internal Server Error: /servicos/servicos-abertos/
Traceback (most recent call last):
  File "C:\projetos\speednetwork\venv\lib\site-packages\django\template\backends\django.py", line 61, in render
    return self.template.render(context)
  File "C:\projetos\speednetwork\venv\lib\site-packages\django\template\base.py", line 171, in render
    return self._render(context)
  File "C:\projetos\speednetwork\venv\lib\site-packages\django\template\base.py", line 163, in _render
    return self.nodelist.render(context)
  File "C:\projetos\speednetwork\venv\lib\site-packages\django\template\base.py", line 936, in render
    bit = node.render_annotated(context)
  File "C:\projetos\speednetwork\venv\lib\site-packages\django\template\base.py", line 903, in render_annotated
    return self.render(context)
  File "C:\projetos\speednetwork\venv\lib\site-packages\django\template\loader_tags.py", line 150, in render
    return compiled_parent._render(context)
  File "C:\projetos\speednetwork\venv\lib\site-packages\django\template\base.py", line 163, in _render
    return self.nodelist.render(context)
  File "C:\projetos\speednetwork\venv\lib\site-packages\django\template\base.py", line 936, in render
    bit = node.render_annotated(context)
  File "C:\projetos\speednetwork\venv\lib\site-packages\django\template\base.py", line 903, in render_annotated
    return self.render(context)
  File "C:\projetos\speednetwork\venv\lib\site-packages\django\template\loader_tags.py", line 62, in render
    result = block.nodelist.render(context)
  File "C:\projetos\speednetwork\venv\lib\site-packages\django\template\base.py", line 936, in render
    bit = node.render_annotated(context)
  File "C:\projetos\speednetwork\venv\lib\site-packages\django\template\base.py", line 903, in render_annotated
    return self.render(context)
  File "C:\projetos\speednetwork\venv\lib\site-packages\django\template\loader_tags.py", line 176, in render
    template = context.template.engine.get_template(template_name)
  File "C:\projetos\speednetwork\venv\lib\site-packages\django\template\engine.py", line 143, in get_template
    template, origin = self.find_template(template_name)
  File "C:\projetos\speednetwork\venv\lib\site-packages\django\template\engine.py", line 129, in find_template
    raise TemplateDoesNotExist(name, tried=tried)
django.template.exceptions.TemplateDoesNotExist: apps/services/templates/services/servicos-abertos.html

The above exception was the direct cause of the following exception:

Traceback (most recent call last):
  File "C:\projetos\speednetwork\venv\lib\site-packages\django\core\handlers\exception.py", line 34, in inner
    response = get_response(request)
  File "C:\projetos\speednetwork\venv\lib\site-packages\django\core\handlers\base.py", line 115, in _get_response
    response = self.process_exception_by_middleware(e, request)
  File "C:\projetos\speednetwork\venv\lib\site-packages\django\core\handlers\base.py", line 113, in _get_response
    response = wrapped_callback(request, *callback_args, **callback_kwargs)
  File "C:\projetos\speednetwork\apps\services\views.py", line 156, in ServicosAbertos
    return render(request, 'services/servicos-abertos.html', context)
  File "C:\projetos\speednetwork\venv\lib\site-packages\django\shortcuts.py", line 19, in render
    content = loader.render_to_string(template_name, context, request, using=using)
  File "C:\projetos\speednetwork\venv\lib\site-packages\django\template\loader.py", line 62, in render_to_string
    return template.render(context, request)
  File "C:\projetos\speednetwork\venv\lib\site-packages\django\template\backends\django.py", line 63, in render
    reraise(exc, self.backend)
  File "C:\projetos\speednetwork\venv\lib\site-packages\django\template\backends\django.py", line 84, in reraise
    raise new from exc
django.template.exceptions.TemplateDoesNotExist: apps/services/templates/services/servicos-abertos.html
"GET /servicos/servicos-abertos/ HTTP/1.1" 500 184896
Internal Server Error: /servicos/servicos-abertos/
Traceback (most recent call last):
  File "C:\projetos\speednetwork\venv\lib\site-packages\django\template\backends\django.py", line 61, in render
    return self.template.render(context)
  File "C:\projetos\speednetwork\venv\lib\site-packages\django\template\base.py", line 171, in render
    return self._render(context)
  File "C:\projetos\speednetwork\venv\lib\site-packages\django\template\base.py", line 163, in _render
    return self.nodelist.render(context)
  File "C:\projetos\speednetwork\venv\lib\site-packages\django\template\base.py", line 936, in render
    bit = node.render_annotated(context)
  File "C:\projetos\speednetwork\venv\lib\site-packages\django\template\base.py", line 903, in render_annotated
    return self.render(context)
  File "C:\projetos\speednetwork\venv\lib\site-packages\django\template\loader_tags.py", line 150, in render
    return compiled_parent._render(context)
  File "C:\projetos\speednetwork\venv\lib\site-packages\django\template\base.py", line 163, in _render
    return self.nodelist.render(context)
  File "C:\projetos\speednetwork\venv\lib\site-packages\django\template\base.py", line 936, in render
    bit = node.render_annotated(context)
  File "C:\projetos\speednetwork\venv\lib\site-packages\django\template\base.py", line 903, in render_annotated
    return self.render(context)
  File "C:\projetos\speednetwork\venv\lib\site-packages\django\template\loader_tags.py", line 62, in render
    result = block.nodelist.render(context)
  File "C:\projetos\speednetwork\venv\lib\site-packages\django\template\base.py", line 936, in render
    bit = node.render_annotated(context)
  File "C:\projetos\speednetwork\venv\lib\site-packages\django\template\base.py", line 903, in render_annotated
    return self.render(context)
  File "C:\projetos\speednetwork\venv\lib\site-packages\django\template\loader_tags.py", line 176, in render
    template = context.template.engine.get_template(template_name)
  File "C:\projetos\speednetwork\venv\lib\site-packages\django\template\engine.py", line 143, in get_template
    template, origin = self.find_template(template_name)
  File "C:\projetos\speednetwork\venv\lib\site-packages\django\template\engine.py", line 129, in find_template
    raise TemplateDoesNotExist(name, tried=tried)
django.template.exceptions.TemplateDoesNotExist: /services/servicos-abertos.html

The above exception was the direct cause of the following exception:

Traceback (most recent call last):
  File "C:\projetos\speednetwork\venv\lib\site-packages\django\core\handlers\exception.py", line 34, in inner
    response = get_response(request)
  File "C:\projetos\speednetwork\venv\lib\site-packages\django\core\handlers\base.py", line 115, in _get_response
    response = self.process_exception_by_middleware(e, request)
  File "C:\projetos\speednetwork\venv\lib\site-packages\django\core\handlers\base.py", line 113, in _get_response
    response = wrapped_callback(request, *callback_args, **callback_kwargs)
  File "C:\projetos\speednetwork\apps\services\views.py", line 156, in ServicosAbertos
    return render(request, 'services/servicos-abertos.html', context)
  File "C:\projetos\speednetwork\venv\lib\site-packages\django\shortcuts.py", line 19, in render
    content = loader.render_to_string(template_name, context, request, using=using)
  File "C:\projetos\speednetwork\venv\lib\site-packages\django\template\loader.py", line 62, in render_to_string
    return template.render(context, request)
  File "C:\projetos\speednetwork\venv\lib\site-packages\django\template\backends\django.py", line 63, in render
    reraise(exc, self.backend)
  File "C:\projetos\speednetwork\venv\lib\site-packages\django\template\backends\django.py", line 84, in reraise
    raise new from exc
django.template.exceptions.TemplateDoesNotExist: /services/servicos-abertos.html
"GET /servicos/servicos-abertos/ HTTP/1.1" 500 174249
Internal Server Error: /servicos/servicos-abertos/
Traceback (most recent call last):
  File "C:\projetos\speednetwork\venv\lib\site-packages\django\template\backends\django.py", line 61, in render
    return self.template.render(context)
  File "C:\projetos\speednetwork\venv\lib\site-packages\django\template\base.py", line 171, in render
    return self._render(context)
  File "C:\projetos\speednetwork\venv\lib\site-packages\django\template\base.py", line 163, in _render
    return self.nodelist.render(context)
  File "C:\projetos\speednetwork\venv\lib\site-packages\django\template\base.py", line 936, in render
    bit = node.render_annotated(context)
  File "C:\projetos\speednetwork\venv\lib\site-packages\django\template\base.py", line 903, in render_annotated
    return self.render(context)
  File "C:\projetos\speednetwork\venv\lib\site-packages\django\template\loader_tags.py", line 150, in render
    return compiled_parent._render(context)
  File "C:\projetos\speednetwork\venv\lib\site-packages\django\template\base.py", line 163, in _render
    return self.nodelist.render(context)
  File "C:\projetos\speednetwork\venv\lib\site-packages\django\template\base.py", line 936, in render
    bit = node.render_annotated(context)
  File "C:\projetos\speednetwork\venv\lib\site-packages\django\template\base.py", line 903, in render_annotated
    return self.render(context)
  File "C:\projetos\speednetwork\venv\lib\site-packages\django\template\loader_tags.py", line 62, in render
    result = block.nodelist.render(context)
  File "C:\projetos\speednetwork\venv\lib\site-packages\django\template\base.py", line 936, in render
    bit = node.render_annotated(context)
  File "C:\projetos\speednetwork\venv\lib\site-packages\django\template\base.py", line 903, in render_annotated
    return self.render(context)
  File "C:\projetos\speednetwork\venv\lib\site-packages\django\template\loader_tags.py", line 176, in render
    template = context.template.engine.get_template(template_name)
  File "C:\projetos\speednetwork\venv\lib\site-packages\django\template\engine.py", line 143, in get_template
    template, origin = self.find_template(template_name)
  File "C:\projetos\speednetwork\venv\lib\site-packages\django\template\engine.py", line 129, in find_template
    raise TemplateDoesNotExist(name, tried=tried)
django.template.exceptions.TemplateDoesNotExist: /services/servicos-abertos.html

The above exception was the direct cause of the following exception:

Traceback (most recent call last):
  File "C:\projetos\speednetwork\venv\lib\site-packages\django\core\handlers\exception.py", line 34, in inner
    response = get_response(request)
  File "C:\projetos\speednetwork\venv\lib\site-packages\django\core\handlers\base.py", line 115, in _get_response
    response = self.process_exception_by_middleware(e, request)
  File "C:\projetos\speednetwork\venv\lib\site-packages\django\core\handlers\base.py", line 113, in _get_response
    response = wrapped_callback(request, *callback_args, **callback_kwargs)
  File "C:\projetos\speednetwork\apps\services\views.py", line 156, in ServicosAbertos
    return render(request, 'services/servicos-abertos.html', context)
  File "C:\projetos\speednetwork\venv\lib\site-packages\django\shortcuts.py", line 19, in render
    content = loader.render_to_string(template_name, context, request, using=using)
  File "C:\projetos\speednetwork\venv\lib\site-packages\django\template\loader.py", line 62, in render_to_string
    return template.render(context, request)
  File "C:\projetos\speednetwork\venv\lib\site-packages\django\template\backends\django.py", line 63, in render
    reraise(exc, self.backend)
  File "C:\projetos\speednetwork\venv\lib\site-packages\django\template\backends\django.py", line 84, in reraise
    raise new from exc
django.template.exceptions.TemplateDoesNotExist: /services/servicos-abertos.html
"GET /servicos/servicos-abertos/ HTTP/1.1" 500 174249
Internal Server Error: /servicos/servicos-abertos/
Traceback (most recent call last):
  File "C:\projetos\speednetwork\venv\lib\site-packages\django\template\backends\django.py", line 61, in render
    return self.template.render(context)
  File "C:\projetos\speednetwork\venv\lib\site-packages\django\template\base.py", line 171, in render
    return self._render(context)
  File "C:\projetos\speednetwork\venv\lib\site-packages\django\template\base.py", line 163, in _render
    return self.nodelist.render(context)
  File "C:\projetos\speednetwork\venv\lib\site-packages\django\template\base.py", line 936, in render
    bit = node.render_annotated(context)
  File "C:\projetos\speednetwork\venv\lib\site-packages\django\template\base.py", line 903, in render_annotated
    return self.render(context)
  File "C:\projetos\speednetwork\venv\lib\site-packages\django\template\loader_tags.py", line 150, in render
    return compiled_parent._render(context)
  File "C:\projetos\speednetwork\venv\lib\site-packages\django\template\base.py", line 163, in _render
    return self.nodelist.render(context)
  File "C:\projetos\speednetwork\venv\lib\site-packages\django\template\base.py", line 936, in render
    bit = node.render_annotated(context)
  File "C:\projetos\speednetwork\venv\lib\site-packages\django\template\base.py", line 903, in render_annotated
    return self.render(context)
  File "C:\projetos\speednetwork\venv\lib\site-packages\django\template\loader_tags.py", line 62, in render
    result = block.nodelist.render(context)
  File "C:\projetos\speednetwork\venv\lib\site-packages\django\template\base.py", line 936, in render
    bit = node.render_annotated(context)
  File "C:\projetos\speednetwork\venv\lib\site-packages\django\template\base.py", line 903, in render_annotated
    return self.render(context)
  File "C:\projetos\speednetwork\venv\lib\site-packages\django\template\loader_tags.py", line 176, in render
    template = context.template.engine.get_template(template_name)
  File "C:\projetos\speednetwork\venv\lib\site-packages\django\template\engine.py", line 143, in get_template
    template, origin = self.find_template(template_name)
  File "C:\projetos\speednetwork\venv\lib\site-packages\django\template\engine.py", line 129, in find_template
    raise TemplateDoesNotExist(name, tried=tried)
django.template.exceptions.TemplateDoesNotExist: /services/servicos-abertos.html

The above exception was the direct cause of the following exception:

Traceback (most recent call last):
  File "C:\projetos\speednetwork\venv\lib\site-packages\django\core\handlers\exception.py", line 34, in inner
    response = get_response(request)
  File "C:\projetos\speednetwork\venv\lib\site-packages\django\core\handlers\base.py", line 115, in _get_response
    response = self.process_exception_by_middleware(e, request)
  File "C:\projetos\speednetwork\venv\lib\site-packages\django\core\handlers\base.py", line 113, in _get_response
    response = wrapped_callback(request, *callback_args, **callback_kwargs)
  File "C:\projetos\speednetwork\apps\services\views.py", line 156, in ServicosAbertos
    return render(request, 'services/servicos-abertos.html', context)
  File "C:\projetos\speednetwork\venv\lib\site-packages\django\shortcuts.py", line 19, in render
    content = loader.render_to_string(template_name, context, request, using=using)
  File "C:\projetos\speednetwork\venv\lib\site-packages\django\template\loader.py", line 62, in render_to_string
    return template.render(context, request)
  File "C:\projetos\speednetwork\venv\lib\site-packages\django\template\backends\django.py", line 63, in render
    reraise(exc, self.backend)
  File "C:\projetos\speednetwork\venv\lib\site-packages\django\template\backends\django.py", line 84, in reraise
    raise new from exc
django.template.exceptions.TemplateDoesNotExist: /services/servicos-abertos.html
"GET /servicos/servicos-abertos/ HTTP/1.1" 500 174112
Internal Server Error: /servicos/editar-servico-agendado/25
Traceback (most recent call last):
  File "C:\projetos\speednetwork\venv\lib\site-packages\django\core\handlers\exception.py", line 34, in inner
    response = get_response(request)
  File "C:\projetos\speednetwork\venv\lib\site-packages\django\core\handlers\base.py", line 115, in _get_response
    response = self.process_exception_by_middleware(e, request)
  File "C:\projetos\speednetwork\venv\lib\site-packages\django\core\handlers\base.py", line 113, in _get_response
    response = wrapped_callback(request, *callback_args, **callback_kwargs)
  File "C:\projetos\speednetwork\apps\services\views.py", line 167, in EditarServicoAgendado
    return render(request, 'services/editar-servico.html', {'form': form})
  File "C:\projetos\speednetwork\venv\lib\site-packages\django\shortcuts.py", line 19, in render
    content = loader.render_to_string(template_name, context, request, using=using)
  File "C:\projetos\speednetwork\venv\lib\site-packages\django\template\loader.py", line 62, in render_to_string
    return template.render(context, request)
  File "C:\projetos\speednetwork\venv\lib\site-packages\django\template\backends\django.py", line 61, in render
    return self.template.render(context)
  File "C:\projetos\speednetwork\venv\lib\site-packages\django\template\base.py", line 171, in render
    return self._render(context)
  File "C:\projetos\speednetwork\venv\lib\site-packages\django\template\base.py", line 163, in _render
    return self.nodelist.render(context)
  File "C:\projetos\speednetwork\venv\lib\site-packages\django\template\base.py", line 936, in render
    bit = node.render_annotated(context)
  File "C:\projetos\speednetwork\venv\lib\site-packages\django\template\base.py", line 903, in render_annotated
    return self.render(context)
  File "C:\projetos\speednetwork\venv\lib\site-packages\django\template\loader_tags.py", line 150, in render
    return compiled_parent._render(context)
  File "C:\projetos\speednetwork\venv\lib\site-packages\django\template\base.py", line 163, in _render
    return self.nodelist.render(context)
  File "C:\projetos\speednetwork\venv\lib\site-packages\django\template\base.py", line 936, in render
    bit = node.render_annotated(context)
  File "C:\projetos\speednetwork\venv\lib\site-packages\django\template\base.py", line 903, in render_annotated
    return self.render(context)
  File "C:\projetos\speednetwork\venv\lib\site-packages\django\template\loader_tags.py", line 62, in render
    result = block.nodelist.render(context)
  File "C:\projetos\speednetwork\venv\lib\site-packages\django\template\base.py", line 936, in render
    bit = node.render_annotated(context)
  File "C:\projetos\speednetwork\venv\lib\site-packages\django\template\base.py", line 903, in render_annotated
    return self.render(context)
  File "C:\projetos\speednetwork\venv\lib\site-packages\django\template\base.py", line 986, in render
    output = self.filter_expression.resolve(context)
  File "C:\projetos\speednetwork\venv\lib\site-packages\django\template\base.py", line 697, in resolve
    new_obj = func(obj, *arg_vals)
  File "C:\projetos\speednetwork\venv\lib\site-packages\crispy_forms\templatetags\crispy_forms_filters.py", line 102, in as_crispy_field
    raise CrispyError("|as_crispy_field got passed an invalid or inexistent field")
crispy_forms.exceptions.CrispyError: |as_crispy_field got passed an invalid or inexistent field
"GET /servicos/editar-servico-agendado/25 HTTP/1.1" 500 163127
Internal Server Error: /servicos/editar-servico-agendado/25
Traceback (most recent call last):
  File "C:\projetos\speednetwork\venv\lib\site-packages\django\core\handlers\exception.py", line 34, in inner
    response = get_response(request)
  File "C:\projetos\speednetwork\venv\lib\site-packages\django\core\handlers\base.py", line 115, in _get_response
    response = self.process_exception_by_middleware(e, request)
  File "C:\projetos\speednetwork\venv\lib\site-packages\django\core\handlers\base.py", line 113, in _get_response
    response = wrapped_callback(request, *callback_args, **callback_kwargs)
  File "C:\projetos\speednetwork\apps\services\views.py", line 167, in EditarServicoAgendado
    return render(request, 'services/editar-servico.html', {'form': form})
  File "C:\projetos\speednetwork\venv\lib\site-packages\django\shortcuts.py", line 19, in render
    content = loader.render_to_string(template_name, context, request, using=using)
  File "C:\projetos\speednetwork\venv\lib\site-packages\django\template\loader.py", line 62, in render_to_string
    return template.render(context, request)
  File "C:\projetos\speednetwork\venv\lib\site-packages\django\template\backends\django.py", line 61, in render
    return self.template.render(context)
  File "C:\projetos\speednetwork\venv\lib\site-packages\django\template\base.py", line 171, in render
    return self._render(context)
  File "C:\projetos\speednetwork\venv\lib\site-packages\django\template\base.py", line 163, in _render
    return self.nodelist.render(context)
  File "C:\projetos\speednetwork\venv\lib\site-packages\django\template\base.py", line 936, in render
    bit = node.render_annotated(context)
  File "C:\projetos\speednetwork\venv\lib\site-packages\django\template\base.py", line 903, in render_annotated
    return self.render(context)
  File "C:\projetos\speednetwork\venv\lib\site-packages\django\template\loader_tags.py", line 150, in render
    return compiled_parent._render(context)
  File "C:\projetos\speednetwork\venv\lib\site-packages\django\template\base.py", line 163, in _render
    return self.nodelist.render(context)
  File "C:\projetos\speednetwork\venv\lib\site-packages\django\template\base.py", line 936, in render
    bit = node.render_annotated(context)
  File "C:\projetos\speednetwork\venv\lib\site-packages\django\template\base.py", line 903, in render_annotated
    return self.render(context)
  File "C:\projetos\speednetwork\venv\lib\site-packages\django\template\loader_tags.py", line 62, in render
    result = block.nodelist.render(context)
  File "C:\projetos\speednetwork\venv\lib\site-packages\django\template\base.py", line 936, in render
    bit = node.render_annotated(context)
  File "C:\projetos\speednetwork\venv\lib\site-packages\django\template\base.py", line 903, in render_annotated
    return self.render(context)
  File "C:\projetos\speednetwork\venv\lib\site-packages\django\template\base.py", line 986, in render
    output = self.filter_expression.resolve(context)
  File "C:\projetos\speednetwork\venv\lib\site-packages\django\template\base.py", line 697, in resolve
    new_obj = func(obj, *arg_vals)
  File "C:\projetos\speednetwork\venv\lib\site-packages\crispy_forms\templatetags\crispy_forms_filters.py", line 102, in as_crispy_field
    raise CrispyError("|as_crispy_field got passed an invalid or inexistent field")
crispy_forms.exceptions.CrispyError: |as_crispy_field got passed an invalid or inexistent field
"GET /servicos/editar-servico-agendado/25 HTTP/1.1" 500 162919
Internal Server Error: /admin/services/servico/
Traceback (most recent call last):
  File "C:\projetos\speednetwork\venv\lib\site-packages\django\core\handlers\exception.py", line 34, in inner
    response = get_response(request)
  File "C:\projetos\speednetwork\venv\lib\site-packages\django\core\handlers\base.py", line 115, in _get_response
    response = self.process_exception_by_middleware(e, request)
  File "C:\projetos\speednetwork\venv\lib\site-packages\django\core\handlers\base.py", line 113, in _get_response
    response = wrapped_callback(request, *callback_args, **callback_kwargs)
  File "C:\projetos\speednetwork\venv\lib\site-packages\django\contrib\admin\options.py", line 607, in wrapper
    return self.admin_site.admin_view(view)(*args, **kwargs)
  File "C:\projetos\speednetwork\venv\lib\site-packages\django\utils\decorators.py", line 130, in _wrapped_view
    response = view_func(request, *args, **kwargs)
  File "C:\projetos\speednetwork\venv\lib\site-packages\django\views\decorators\cache.py", line 44, in _wrapped_view_func
    response = view_func(request, *args, **kwargs)
  File "C:\projetos\speednetwork\venv\lib\site-packages\django\contrib\admin\sites.py", line 231, in inner
    return view(request, *args, **kwargs)
  File "C:\projetos\speednetwork\venv\lib\site-packages\django\utils\decorators.py", line 43, in _wrapper
    return bound_method(*args, **kwargs)
  File "C:\projetos\speednetwork\venv\lib\site-packages\django\utils\decorators.py", line 130, in _wrapped_view
    response = view_func(request, *args, **kwargs)
  File "C:\projetos\speednetwork\venv\lib\site-packages\django\contrib\admin\options.py", line 1678, in changelist_view
    cl = self.get_changelist_instance(request)
  File "C:\projetos\speednetwork\venv\lib\site-packages\django\contrib\admin\options.py", line 728, in get_changelist_instance
    return ChangeList(
  File "C:\projetos\speednetwork\venv\lib\site-packages\django\contrib\admin\views\main.py", line 97, in __init__
    self.queryset = self.get_queryset(request)
  File "C:\projetos\speednetwork\venv\lib\site-packages\django\contrib\admin\views\main.py", line 457, in get_queryset
    qs, search_use_distinct = self.model_admin.get_search_results(request, qs, self.query)
  File "C:\projetos\speednetwork\venv\lib\site-packages\django\contrib\admin\options.py", line 1016, in get_search_results
    queryset = queryset.filter(reduce(operator.or_, or_queries))
  File "C:\projetos\speednetwork\venv\lib\site-packages\django\db\models\query.py", line 904, in filter
    return self._filter_or_exclude(False, *args, **kwargs)
  File "C:\projetos\speednetwork\venv\lib\site-packages\django\db\models\query.py", line 923, in _filter_or_exclude
    clone.query.add_q(Q(*args, **kwargs))
  File "C:\projetos\speednetwork\venv\lib\site-packages\django\db\models\sql\query.py", line 1337, in add_q
    clause, _ = self._add_q(q_object, self.used_aliases)
  File "C:\projetos\speednetwork\venv\lib\site-packages\django\db\models\sql\query.py", line 1357, in _add_q
    child_clause, needed_inner = self._add_q(
  File "C:\projetos\speednetwork\venv\lib\site-packages\django\db\models\sql\query.py", line 1362, in _add_q
    child_clause, needed_inner = self.build_filter(
  File "C:\projetos\speednetwork\venv\lib\site-packages\django\db\models\sql\query.py", line 1239, in build_filter
    lookups, parts, reffed_expression = self.solve_lookup_type(arg)
  File "C:\projetos\speednetwork\venv\lib\site-packages\django\db\models\sql\query.py", line 1077, in solve_lookup_type
    _, field, _, lookup_parts = self.names_to_path(lookup_splitted, self.get_meta())
  File "C:\projetos\speednetwork\venv\lib\site-packages\django\db\models\sql\query.py", line 1466, in names_to_path
    raise FieldError("Cannot resolve keyword '%s' into field. "
django.core.exceptions.FieldError: Cannot resolve keyword 'usuario_voip' into field. Choices are: agendado_por, agendado_por_id, categoria, categoria_id, contato_servico, criado_por, criado_por_id, data_agendada, data_criacao, data_finalizacao, endereco_servico, finalizado_por, finalizado_por_id, funcionario_servico, funcionario_servico_id, gerarresultadosdiarios, hora_agendada, id, material_utilizado, observacao, plano_internet, plano_internet_id, servico_executado, servico_para_executar, status_agendado, status_analise, status_concluido
"GET /admin/services/servico/?q=maio HTTP/1.1" 500 171933
Internal Server Error: /admin/services/servico/
Traceback (most recent call last):
  File "C:\projetos\speednetwork\venv\lib\site-packages\django\core\handlers\exception.py", line 34, in inner
    response = get_response(request)
  File "C:\projetos\speednetwork\venv\lib\site-packages\django\core\handlers\base.py", line 115, in _get_response
    response = self.process_exception_by_middleware(e, request)
  File "C:\projetos\speednetwork\venv\lib\site-packages\django\core\handlers\base.py", line 113, in _get_response
    response = wrapped_callback(request, *callback_args, **callback_kwargs)
  File "C:\projetos\speednetwork\venv\lib\site-packages\django\contrib\admin\options.py", line 607, in wrapper
    return self.admin_site.admin_view(view)(*args, **kwargs)
  File "C:\projetos\speednetwork\venv\lib\site-packages\django\utils\decorators.py", line 130, in _wrapped_view
    response = view_func(request, *args, **kwargs)
  File "C:\projetos\speednetwork\venv\lib\site-packages\django\views\decorators\cache.py", line 44, in _wrapped_view_func
    response = view_func(request, *args, **kwargs)
  File "C:\projetos\speednetwork\venv\lib\site-packages\django\contrib\admin\sites.py", line 231, in inner
    return view(request, *args, **kwargs)
  File "C:\projetos\speednetwork\venv\lib\site-packages\django\utils\decorators.py", line 43, in _wrapper
    return bound_method(*args, **kwargs)
  File "C:\projetos\speednetwork\venv\lib\site-packages\django\utils\decorators.py", line 130, in _wrapped_view
    response = view_func(request, *args, **kwargs)
  File "C:\projetos\speednetwork\venv\lib\site-packages\django\contrib\admin\options.py", line 1678, in changelist_view
    cl = self.get_changelist_instance(request)
  File "C:\projetos\speednetwork\venv\lib\site-packages\django\contrib\admin\options.py", line 728, in get_changelist_instance
    return ChangeList(
  File "C:\projetos\speednetwork\venv\lib\site-packages\django\contrib\admin\views\main.py", line 97, in __init__
    self.queryset = self.get_queryset(request)
  File "C:\projetos\speednetwork\venv\lib\site-packages\django\contrib\admin\views\main.py", line 457, in get_queryset
    qs, search_use_distinct = self.model_admin.get_search_results(request, qs, self.query)
  File "C:\projetos\speednetwork\venv\lib\site-packages\django\contrib\admin\options.py", line 1016, in get_search_results
    queryset = queryset.filter(reduce(operator.or_, or_queries))
  File "C:\projetos\speednetwork\venv\lib\site-packages\django\db\models\query.py", line 904, in filter
    return self._filter_or_exclude(False, *args, **kwargs)
  File "C:\projetos\speednetwork\venv\lib\site-packages\django\db\models\query.py", line 923, in _filter_or_exclude
    clone.query.add_q(Q(*args, **kwargs))
  File "C:\projetos\speednetwork\venv\lib\site-packages\django\db\models\sql\query.py", line 1337, in add_q
    clause, _ = self._add_q(q_object, self.used_aliases)
  File "C:\projetos\speednetwork\venv\lib\site-packages\django\db\models\sql\query.py", line 1357, in _add_q
    child_clause, needed_inner = self._add_q(
  File "C:\projetos\speednetwork\venv\lib\site-packages\django\db\models\sql\query.py", line 1362, in _add_q
    child_clause, needed_inner = self.build_filter(
  File "C:\projetos\speednetwork\venv\lib\site-packages\django\db\models\sql\query.py", line 1239, in build_filter
    lookups, parts, reffed_expression = self.solve_lookup_type(arg)
  File "C:\projetos\speednetwork\venv\lib\site-packages\django\db\models\sql\query.py", line 1077, in solve_lookup_type
    _, field, _, lookup_parts = self.names_to_path(lookup_splitted, self.get_meta())
  File "C:\projetos\speednetwork\venv\lib\site-packages\django\db\models\sql\query.py", line 1466, in names_to_path
    raise FieldError("Cannot resolve keyword '%s' into field. "
django.core.exceptions.FieldError: Cannot resolve keyword 'usuario_voip' into field. Choices are: agendado_por, agendado_por_id, categoria, categoria_id, contato_servico, criado_por, criado_por_id, data_agendada, data_criacao, data_finalizacao, endereco_servico, finalizado_por, finalizado_por_id, funcionario_servico, funcionario_servico_id, gerarresultadosdiarios, hora_agendada, id, material_utilizado, observacao, plano_internet, plano_internet_id, servico_executado, servico_para_executar, status_agendado, status_analise, status_concluido
"GET /admin/services/servico/?q=maio HTTP/1.1" 500 171933
Internal Server Error: /admin/services/servico/
Traceback (most recent call last):
  File "C:\projetos\speednetwork\venv\lib\site-packages\django\core\handlers\exception.py", line 34, in inner
    response = get_response(request)
  File "C:\projetos\speednetwork\venv\lib\site-packages\django\core\handlers\base.py", line 115, in _get_response
    response = self.process_exception_by_middleware(e, request)
  File "C:\projetos\speednetwork\venv\lib\site-packages\django\core\handlers\base.py", line 113, in _get_response
    response = wrapped_callback(request, *callback_args, **callback_kwargs)
  File "C:\projetos\speednetwork\venv\lib\site-packages\django\contrib\admin\options.py", line 607, in wrapper
    return self.admin_site.admin_view(view)(*args, **kwargs)
  File "C:\projetos\speednetwork\venv\lib\site-packages\django\utils\decorators.py", line 130, in _wrapped_view
    response = view_func(request, *args, **kwargs)
  File "C:\projetos\speednetwork\venv\lib\site-packages\django\views\decorators\cache.py", line 44, in _wrapped_view_func
    response = view_func(request, *args, **kwargs)
  File "C:\projetos\speednetwork\venv\lib\site-packages\django\contrib\admin\sites.py", line 231, in inner
    return view(request, *args, **kwargs)
  File "C:\projetos\speednetwork\venv\lib\site-packages\django\utils\decorators.py", line 43, in _wrapper
    return bound_method(*args, **kwargs)
  File "C:\projetos\speednetwork\venv\lib\site-packages\django\utils\decorators.py", line 130, in _wrapped_view
    response = view_func(request, *args, **kwargs)
  File "C:\projetos\speednetwork\venv\lib\site-packages\django\contrib\admin\options.py", line 1678, in changelist_view
    cl = self.get_changelist_instance(request)
  File "C:\projetos\speednetwork\venv\lib\site-packages\django\contrib\admin\options.py", line 728, in get_changelist_instance
    return ChangeList(
  File "C:\projetos\speednetwork\venv\lib\site-packages\django\contrib\admin\views\main.py", line 97, in __init__
    self.queryset = self.get_queryset(request)
  File "C:\projetos\speednetwork\venv\lib\site-packages\django\contrib\admin\views\main.py", line 457, in get_queryset
    qs, search_use_distinct = self.model_admin.get_search_results(request, qs, self.query)
  File "C:\projetos\speednetwork\venv\lib\site-packages\django\contrib\admin\options.py", line 1016, in get_search_results
    queryset = queryset.filter(reduce(operator.or_, or_queries))
  File "C:\projetos\speednetwork\venv\lib\site-packages\django\db\models\query.py", line 904, in filter
    return self._filter_or_exclude(False, *args, **kwargs)
  File "C:\projetos\speednetwork\venv\lib\site-packages\django\db\models\query.py", line 923, in _filter_or_exclude
    clone.query.add_q(Q(*args, **kwargs))
  File "C:\projetos\speednetwork\venv\lib\site-packages\django\db\models\sql\query.py", line 1337, in add_q
    clause, _ = self._add_q(q_object, self.used_aliases)
  File "C:\projetos\speednetwork\venv\lib\site-packages\django\db\models\sql\query.py", line 1357, in _add_q
    child_clause, needed_inner = self._add_q(
  File "C:\projetos\speednetwork\venv\lib\site-packages\django\db\models\sql\query.py", line 1362, in _add_q
    child_clause, needed_inner = self.build_filter(
  File "C:\projetos\speednetwork\venv\lib\site-packages\django\db\models\sql\query.py", line 1239, in build_filter
    lookups, parts, reffed_expression = self.solve_lookup_type(arg)
  File "C:\projetos\speednetwork\venv\lib\site-packages\django\db\models\sql\query.py", line 1077, in solve_lookup_type
    _, field, _, lookup_parts = self.names_to_path(lookup_splitted, self.get_meta())
  File "C:\projetos\speednetwork\venv\lib\site-packages\django\db\models\sql\query.py", line 1466, in names_to_path
    raise FieldError("Cannot resolve keyword '%s' into field. "
django.core.exceptions.FieldError: Cannot resolve keyword 'usuario_voip' into field. Choices are: agendado_por, agendado_por_id, categoria, categoria_id, contato_servico, criado_por, criado_por_id, data_agendada, data_criacao, data_finalizacao, endereco_servico, finalizado_por, finalizado_por_id, funcionario_servico, funcionario_servico_id, gerarresultadosdiarios, hora_agendada, id, material_utilizado, observacao, plano_internet, plano_internet_id, servico_executado, servico_para_executar, status_agendado, status_analise, status_concluido
"GET /admin/services/servico/?q=ma HTTP/1.1" 500 171310
Internal Server Error: /admin/services/servico/
Traceback (most recent call last):
  File "C:\projetos\speednetwork\venv\lib\site-packages\django\core\handlers\exception.py", line 34, in inner
    response = get_response(request)
  File "C:\projetos\speednetwork\venv\lib\site-packages\django\core\handlers\base.py", line 115, in _get_response
    response = self.process_exception_by_middleware(e, request)
  File "C:\projetos\speednetwork\venv\lib\site-packages\django\core\handlers\base.py", line 113, in _get_response
    response = wrapped_callback(request, *callback_args, **callback_kwargs)
  File "C:\projetos\speednetwork\venv\lib\site-packages\django\contrib\admin\options.py", line 607, in wrapper
    return self.admin_site.admin_view(view)(*args, **kwargs)
  File "C:\projetos\speednetwork\venv\lib\site-packages\django\utils\decorators.py", line 130, in _wrapped_view
    response = view_func(request, *args, **kwargs)
  File "C:\projetos\speednetwork\venv\lib\site-packages\django\views\decorators\cache.py", line 44, in _wrapped_view_func
    response = view_func(request, *args, **kwargs)
  File "C:\projetos\speednetwork\venv\lib\site-packages\django\contrib\admin\sites.py", line 231, in inner
    return view(request, *args, **kwargs)
  File "C:\projetos\speednetwork\venv\lib\site-packages\django\utils\decorators.py", line 43, in _wrapper
    return bound_method(*args, **kwargs)
  File "C:\projetos\speednetwork\venv\lib\site-packages\django\utils\decorators.py", line 130, in _wrapped_view
    response = view_func(request, *args, **kwargs)
  File "C:\projetos\speednetwork\venv\lib\site-packages\django\contrib\admin\options.py", line 1678, in changelist_view
    cl = self.get_changelist_instance(request)
  File "C:\projetos\speednetwork\venv\lib\site-packages\django\contrib\admin\options.py", line 728, in get_changelist_instance
    return ChangeList(
  File "C:\projetos\speednetwork\venv\lib\site-packages\django\contrib\admin\views\main.py", line 97, in __init__
    self.queryset = self.get_queryset(request)
  File "C:\projetos\speednetwork\venv\lib\site-packages\django\contrib\admin\views\main.py", line 457, in get_queryset
    qs, search_use_distinct = self.model_admin.get_search_results(request, qs, self.query)
  File "C:\projetos\speednetwork\venv\lib\site-packages\django\contrib\admin\options.py", line 1016, in get_search_results
    queryset = queryset.filter(reduce(operator.or_, or_queries))
  File "C:\projetos\speednetwork\venv\lib\site-packages\django\db\models\query.py", line 904, in filter
    return self._filter_or_exclude(False, *args, **kwargs)
  File "C:\projetos\speednetwork\venv\lib\site-packages\django\db\models\query.py", line 923, in _filter_or_exclude
    clone.query.add_q(Q(*args, **kwargs))
  File "C:\projetos\speednetwork\venv\lib\site-packages\django\db\models\sql\query.py", line 1337, in add_q
    clause, _ = self._add_q(q_object, self.used_aliases)
  File "C:\projetos\speednetwork\venv\lib\site-packages\django\db\models\sql\query.py", line 1357, in _add_q
    child_clause, needed_inner = self._add_q(
  File "C:\projetos\speednetwork\venv\lib\site-packages\django\db\models\sql\query.py", line 1362, in _add_q
    child_clause, needed_inner = self.build_filter(
  File "C:\projetos\speednetwork\venv\lib\site-packages\django\db\models\sql\query.py", line 1239, in build_filter
    lookups, parts, reffed_expression = self.solve_lookup_type(arg)
  File "C:\projetos\speednetwork\venv\lib\site-packages\django\db\models\sql\query.py", line 1077, in solve_lookup_type
    _, field, _, lookup_parts = self.names_to_path(lookup_splitted, self.get_meta())
  File "C:\projetos\speednetwork\venv\lib\site-packages\django\db\models\sql\query.py", line 1466, in names_to_path
    raise FieldError("Cannot resolve keyword '%s' into field. "
django.core.exceptions.FieldError: Cannot resolve keyword 'usuario_voip' into field. Choices are: agendado_por, agendado_por_id, categoria, categoria_id, contato_servico, criado_por, criado_por_id, data_agendada, data_criacao, data_finalizacao, endereco_servico, finalizado_por, finalizado_por_id, funcionario_servico, funcionario_servico_id, gerarresultadosdiarios, hora_agendada, id, material_utilizado, observacao, plano_internet, plano_internet_id, servico_executado, servico_para_executar, status_agendado, status_analise, status_concluido
"GET /admin/services/servico/?q=ma HTTP/1.1" 500 171447
Internal Server Error: /
Traceback (most recent call last):
  File "C:\projetos\speednetwork\venv\lib\site-packages\django\core\handlers\exception.py", line 34, in inner
    response = get_response(request)
  File "C:\projetos\speednetwork\venv\lib\site-packages\django\core\handlers\base.py", line 115, in _get_response
    response = self.process_exception_by_middleware(e, request)
  File "C:\projetos\speednetwork\venv\lib\site-packages\django\core\handlers\base.py", line 113, in _get_response
    response = wrapped_callback(request, *callback_args, **callback_kwargs)
  File "C:\projetos\speednetwork\venv\lib\site-packages\django\contrib\auth\decorators.py", line 21, in _wrapped_view
    return view_func(request, *args, **kwargs)
  File "C:\projetos\speednetwork\apps\core\views.py", line 68, in Index
    data_atual = datetime.now()
UnboundLocalError: local variable 'datetime' referenced before assignment
"GET / HTTP/1.1" 500 80382
Internal Server Error: /
Traceback (most recent call last):
  File "C:\projetos\speednetwork\venv\lib\site-packages\django\core\handlers\exception.py", line 34, in inner
    response = get_response(request)
  File "C:\projetos\speednetwork\venv\lib\site-packages\django\core\handlers\base.py", line 115, in _get_response
    response = self.process_exception_by_middleware(e, request)
  File "C:\projetos\speednetwork\venv\lib\site-packages\django\core\handlers\base.py", line 113, in _get_response
    response = wrapped_callback(request, *callback_args, **callback_kwargs)
  File "C:\projetos\speednetwork\venv\lib\site-packages\django\contrib\auth\decorators.py", line 21, in _wrapped_view
    return view_func(request, *args, **kwargs)
  File "C:\projetos\speednetwork\apps\core\views.py", line 69, in Index
    today = datetime.date.today()
AttributeError: 'method_descriptor' object has no attribute 'today'
"GET / HTTP/1.1" 500 80723
Internal Server Error: /
Traceback (most recent call last):
  File "C:\projetos\speednetwork\venv\lib\site-packages\django\core\handlers\exception.py", line 34, in inner
    response = get_response(request)
  File "C:\projetos\speednetwork\venv\lib\site-packages\django\core\handlers\base.py", line 115, in _get_response
    response = self.process_exception_by_middleware(e, request)
  File "C:\projetos\speednetwork\venv\lib\site-packages\django\core\handlers\base.py", line 113, in _get_response
    response = wrapped_callback(request, *callback_args, **callback_kwargs)
  File "C:\projetos\speednetwork\venv\lib\site-packages\django\contrib\auth\decorators.py", line 21, in _wrapped_view
    return view_func(request, *args, **kwargs)
  File "C:\projetos\speednetwork\apps\core\views.py", line 87, in Index
NameError: name 'today' is not defined
"GET / HTTP/1.1" 500 79515
Internal Server Error: /
Traceback (most recent call last):
  File "C:\projetos\speednetwork\venv\lib\site-packages\django\core\handlers\exception.py", line 34, in inner
    response = get_response(request)
  File "C:\projetos\speednetwork\venv\lib\site-packages\django\core\handlers\base.py", line 115, in _get_response
    response = self.process_exception_by_middleware(e, request)
  File "C:\projetos\speednetwork\venv\lib\site-packages\django\core\handlers\base.py", line 113, in _get_response
    response = wrapped_callback(request, *callback_args, **callback_kwargs)
  File "C:\projetos\speednetwork\venv\lib\site-packages\django\contrib\auth\decorators.py", line 21, in _wrapped_view
    return view_func(request, *args, **kwargs)
  File "C:\projetos\speednetwork\apps\core\views.py", line 69, in Index
    todayy = datetime.date.today()
AttributeError: 'method_descriptor' object has no attribute 'today'
"GET / HTTP/1.1" 500 80725
Internal Server Error: /
Traceback (most recent call last):
  File "C:\projetos\speednetwork\venv\lib\site-packages\django\core\handlers\exception.py", line 34, in inner
    response = get_response(request)
  File "C:\projetos\speednetwork\venv\lib\site-packages\django\core\handlers\base.py", line 115, in _get_response
    response = self.process_exception_by_middleware(e, request)
  File "C:\projetos\speednetwork\venv\lib\site-packages\django\core\handlers\base.py", line 113, in _get_response
    response = wrapped_callback(request, *callback_args, **callback_kwargs)
  File "C:\projetos\speednetwork\venv\lib\site-packages\django\contrib\auth\decorators.py", line 21, in _wrapped_view
    return view_func(request, *args, **kwargs)
  File "C:\projetos\speednetwork\apps\core\views.py", line 69, in Index
    todayy = datetime.date.today()
AttributeError: 'method_descriptor' object has no attribute 'today'
"GET / HTTP/1.1" 500 80725
Internal Server Error: /
Traceback (most recent call last):
  File "C:\projetos\speednetwork\venv\lib\site-packages\django\core\handlers\exception.py", line 34, in inner
    response = get_response(request)
  File "C:\projetos\speednetwork\venv\lib\site-packages\django\core\handlers\base.py", line 115, in _get_response
    response = self.process_exception_by_middleware(e, request)
  File "C:\projetos\speednetwork\venv\lib\site-packages\django\core\handlers\base.py", line 113, in _get_response
    response = wrapped_callback(request, *callback_args, **callback_kwargs)
  File "C:\projetos\speednetwork\venv\lib\site-packages\django\contrib\auth\decorators.py", line 21, in _wrapped_view
    return view_func(request, *args, **kwargs)
  File "C:\projetos\speednetwork\apps\core\views.py", line 67, in Index
    this_month = datetime.datetime.now().month
AttributeError: type object 'datetime.datetime' has no attribute 'datetime'
"GET / HTTP/1.1" 500 80400
Internal Server Error: /
Traceback (most recent call last):
  File "C:\projetos\speednetwork\venv\lib\site-packages\django\core\handlers\exception.py", line 34, in inner
    response = get_response(request)
  File "C:\projetos\speednetwork\venv\lib\site-packages\django\core\handlers\base.py", line 115, in _get_response
    response = self.process_exception_by_middleware(e, request)
  File "C:\projetos\speednetwork\venv\lib\site-packages\django\core\handlers\base.py", line 113, in _get_response
    response = wrapped_callback(request, *callback_args, **callback_kwargs)
  File "C:\projetos\speednetwork\venv\lib\site-packages\django\contrib\auth\decorators.py", line 21, in _wrapped_view
    return view_func(request, *args, **kwargs)
  File "C:\projetos\speednetwork\apps\core\views.py", line 92, in Index
    print(install.concluido)
AttributeError: 'list' object has no attribute 'concluido'
"GET / HTTP/1.1" 500 83260
Internal Server Error: /
Traceback (most recent call last):
  File "C:\projetos\speednetwork\venv\lib\site-packages\django\core\handlers\exception.py", line 34, in inner
    response = get_response(request)
  File "C:\projetos\speednetwork\venv\lib\site-packages\django\core\handlers\base.py", line 115, in _get_response
    response = self.process_exception_by_middleware(e, request)
  File "C:\projetos\speednetwork\venv\lib\site-packages\django\core\handlers\base.py", line 113, in _get_response
    response = wrapped_callback(request, *callback_args, **callback_kwargs)
  File "C:\projetos\speednetwork\venv\lib\site-packages\django\contrib\auth\decorators.py", line 21, in _wrapped_view
    return view_func(request, *args, **kwargs)
  File "C:\projetos\speednetwork\apps\core\views.py", line 91, in Index
    install.append(mes)
AttributeError: 'dict' object has no attribute 'append'
"GET / HTTP/1.1" 500 83235
Internal Server Error: /
Traceback (most recent call last):
  File "C:\projetos\speednetwork\venv\lib\site-packages\django\core\handlers\exception.py", line 34, in inner
    response = get_response(request)
  File "C:\projetos\speednetwork\venv\lib\site-packages\django\core\handlers\base.py", line 115, in _get_response
    response = self.process_exception_by_middleware(e, request)
  File "C:\projetos\speednetwork\venv\lib\site-packages\django\core\handlers\base.py", line 113, in _get_response
    response = wrapped_callback(request, *callback_args, **callback_kwargs)
  File "C:\projetos\speednetwork\venv\lib\site-packages\django\contrib\auth\decorators.py", line 21, in _wrapped_view
    return view_func(request, *args, **kwargs)
  File "C:\projetos\speednetwork\apps\core\views.py", line 91, in Index
    install.append(mes)
AttributeError: 'dict' object has no attribute 'append'
"GET / HTTP/1.1" 500 83235
Internal Server Error: /
Traceback (most recent call last):
  File "C:\projetos\speednetwork\venv\lib\site-packages\django\core\handlers\exception.py", line 34, in inner
    response = get_response(request)
  File "C:\projetos\speednetwork\venv\lib\site-packages\django\core\handlers\base.py", line 115, in _get_response
    response = self.process_exception_by_middleware(e, request)
  File "C:\projetos\speednetwork\venv\lib\site-packages\django\core\handlers\base.py", line 113, in _get_response
    response = wrapped_callback(request, *callback_args, **callback_kwargs)
  File "C:\projetos\speednetwork\venv\lib\site-packages\django\contrib\auth\decorators.py", line 21, in _wrapped_view
    return view_func(request, *args, **kwargs)
  File "C:\projetos\speednetwork\apps\core\views.py", line 91, in Index
    install.append(mes)
AttributeError: 'tuple' object has no attribute 'append'
"GET / HTTP/1.1" 500 83239
Internal Server Error: /
Traceback (most recent call last):
  File "C:\projetos\speednetwork\venv\lib\site-packages\django\core\handlers\exception.py", line 34, in inner
    response = get_response(request)
  File "C:\projetos\speednetwork\venv\lib\site-packages\django\core\handlers\base.py", line 115, in _get_response
    response = self.process_exception_by_middleware(e, request)
  File "C:\projetos\speednetwork\venv\lib\site-packages\django\core\handlers\base.py", line 113, in _get_response
    response = wrapped_callback(request, *callback_args, **callback_kwargs)
  File "C:\projetos\speednetwork\venv\lib\site-packages\django\contrib\auth\decorators.py", line 21, in _wrapped_view
    return view_func(request, *args, **kwargs)
  File "C:\projetos\speednetwork\apps\core\views.py", line 91, in Index
    install.append(mes)
AttributeError: 'tuple' object has no attribute 'append'
"GET / HTTP/1.1" 500 83239
Internal Server Error: /vendas/
Traceback (most recent call last):
  File "C:\projetos\speednetwork\venv\lib\site-packages\django\core\handlers\exception.py", line 34, in inner
    response = get_response(request)
  File "C:\projetos\speednetwork\venv\lib\site-packages\django\core\handlers\base.py", line 115, in _get_response
    response = self.process_exception_by_middleware(e, request)
  File "C:\projetos\speednetwork\venv\lib\site-packages\django\core\handlers\base.py", line 113, in _get_response
    response = wrapped_callback(request, *callback_args, **callback_kwargs)
  File "C:\projetos\speednetwork\venv\lib\site-packages\django\contrib\auth\decorators.py", line 21, in _wrapped_view
    return view_func(request, *args, **kwargs)
  File "C:\projetos\speednetwork\apps\sales\views.py", line 99, in Index
    'instalacaoVendedor': instalacaoVendedor,
NameError: name 'instalacaoVendedor' is not defined
"GET /vendas/ HTTP/1.1" 500 83895
Internal Server Error: /vendas/
Traceback (most recent call last):
  File "C:\projetos\speednetwork\venv\lib\site-packages\django\core\handlers\exception.py", line 34, in inner
    response = get_response(request)
  File "C:\projetos\speednetwork\venv\lib\site-packages\django\core\handlers\base.py", line 115, in _get_response
    response = self.process_exception_by_middleware(e, request)
  File "C:\projetos\speednetwork\venv\lib\site-packages\django\core\handlers\base.py", line 113, in _get_response
    response = wrapped_callback(request, *callback_args, **callback_kwargs)
  File "C:\projetos\speednetwork\venv\lib\site-packages\django\contrib\auth\decorators.py", line 21, in _wrapped_view
    return view_func(request, *args, **kwargs)
  File "C:\projetos\speednetwork\apps\sales\views.py", line 99, in Index
    'instalacaoVendedor': instalacaoVendedor,
NameError: name 'instalacaoVendedor' is not defined
"GET /vendas/ HTTP/1.1" 500 83895
Internal Server Error: /vendas/
Traceback (most recent call last):
  File "C:\projetos\speednetwork\venv\lib\site-packages\django\core\handlers\exception.py", line 34, in inner
    response = get_response(request)
  File "C:\projetos\speednetwork\venv\lib\site-packages\django\core\handlers\base.py", line 115, in _get_response
    response = self.process_exception_by_middleware(e, request)
  File "C:\projetos\speednetwork\venv\lib\site-packages\django\core\handlers\base.py", line 113, in _get_response
    response = wrapped_callback(request, *callback_args, **callback_kwargs)
  File "C:\projetos\speednetwork\venv\lib\site-packages\django\contrib\auth\decorators.py", line 21, in _wrapped_view
    return view_func(request, *args, **kwargs)
  File "C:\projetos\speednetwork\apps\sales\views.py", line 36, in Index
    instalacoes_mensais = quantidade_instalacoes_mensais()
  File "C:\projetos\speednetwork\apps\sales\funcoes\dados_instalacoes.py", line 39, in quantidade_instalacoes_mensais
    instalacoes_mensais = Instalacao.objects.annotate(month=TruncMonth('data_finalizacao')).filter(concluido='True').\
NameError: name 'TruncMonth' is not defined
"GET /vendas/ HTTP/1.1" 500 81398
Internal Server Error: /vendas/
Traceback (most recent call last):
  File "C:\projetos\speednetwork\venv\lib\site-packages\django\core\handlers\exception.py", line 34, in inner
    response = get_response(request)
  File "C:\projetos\speednetwork\venv\lib\site-packages\django\core\handlers\base.py", line 115, in _get_response
    response = self.process_exception_by_middleware(e, request)
  File "C:\projetos\speednetwork\venv\lib\site-packages\django\core\handlers\base.py", line 113, in _get_response
    response = wrapped_callback(request, *callback_args, **callback_kwargs)
  File "C:\projetos\speednetwork\venv\lib\site-packages\django\contrib\auth\decorators.py", line 21, in _wrapped_view
    return view_func(request, *args, **kwargs)
  File "C:\projetos\speednetwork\apps\sales\views.py", line 40, in Index
    conheceu_empresa_mes_count = conheceu_empresa_mes_count()
UnboundLocalError: local variable 'conheceu_empresa_mes_count' referenced before assignment
"GET /vendas/ HTTP/1.1" 500 80311
Internal Server Error: /vendas/
Traceback (most recent call last):
  File "C:\projetos\speednetwork\venv\lib\site-packages\django\core\handlers\exception.py", line 34, in inner
    response = get_response(request)
  File "C:\projetos\speednetwork\venv\lib\site-packages\django\core\handlers\base.py", line 115, in _get_response
    response = self.process_exception_by_middleware(e, request)
  File "C:\projetos\speednetwork\venv\lib\site-packages\django\core\handlers\base.py", line 113, in _get_response
    response = wrapped_callback(request, *callback_args, **callback_kwargs)
  File "C:\projetos\speednetwork\venv\lib\site-packages\django\contrib\auth\decorators.py", line 21, in _wrapped_view
    return view_func(request, *args, **kwargs)
  File "C:\projetos\speednetwork\apps\sales\views.py", line 40, in Index
    conheceu_empresa_mes_count = Instalacao.objects.filter(data_finalizacao__month=this_month).count()
UnboundLocalError: local variable 'conheceu_empresa_mes_count' referenced before assignment
"GET /vendas/ HTTP/1.1" 500 80311
Internal Server Error: /vendas/
Traceback (most recent call last):
  File "C:\projetos\speednetwork\venv\lib\site-packages\django\core\handlers\exception.py", line 34, in inner
    response = get_response(request)
  File "C:\projetos\speednetwork\venv\lib\site-packages\django\core\handlers\base.py", line 115, in _get_response
    response = self.process_exception_by_middleware(e, request)
  File "C:\projetos\speednetwork\venv\lib\site-packages\django\core\handlers\base.py", line 113, in _get_response
    response = wrapped_callback(request, *callback_args, **callback_kwargs)
  File "C:\projetos\speednetwork\venv\lib\site-packages\django\contrib\auth\decorators.py", line 21, in _wrapped_view
    return view_func(request, *args, **kwargs)
  File "C:\projetos\speednetwork\apps\sales\views.py", line 40, in Index
    conheceu_empresa_mes_count = Instalacao.objects.filter(data_finalizacao__month=this_month).count()
UnboundLocalError: local variable 'this_month' referenced before assignment
"GET /vendas/ HTTP/1.1" 500 80329
Internal Server Error: /vendas/
Traceback (most recent call last):
  File "C:\projetos\speednetwork\venv\lib\site-packages\django\core\handlers\exception.py", line 34, in inner
    response = get_response(request)
  File "C:\projetos\speednetwork\venv\lib\site-packages\django\core\handlers\base.py", line 115, in _get_response
    response = self.process_exception_by_middleware(e, request)
  File "C:\projetos\speednetwork\venv\lib\site-packages\django\core\handlers\base.py", line 113, in _get_response
    response = wrapped_callback(request, *callback_args, **callback_kwargs)
  File "C:\projetos\speednetwork\venv\lib\site-packages\django\contrib\auth\decorators.py", line 21, in _wrapped_view
    return view_func(request, *args, **kwargs)
  File "C:\projetos\speednetwork\apps\sales\views.py", line 40, in Index
    conheceu_empresa_mes_count = Instalacao.objects.filter(data_finalizacao__month=this_month).count()
UnboundLocalError: local variable 'this_month' referenced before assignment
"GET /vendas/ HTTP/1.1" 500 80329
Internal Server Error: /vendas/
Traceback (most recent call last):
  File "C:\projetos\speednetwork\venv\lib\site-packages\django\core\handlers\exception.py", line 34, in inner
    response = get_response(request)
  File "C:\projetos\speednetwork\venv\lib\site-packages\django\core\handlers\base.py", line 115, in _get_response
    response = self.process_exception_by_middleware(e, request)
  File "C:\projetos\speednetwork\venv\lib\site-packages\django\core\handlers\base.py", line 113, in _get_response
    response = wrapped_callback(request, *callback_args, **callback_kwargs)
  File "C:\projetos\speednetwork\venv\lib\site-packages\django\contrib\auth\decorators.py", line 21, in _wrapped_view
    return view_func(request, *args, **kwargs)
  File "C:\projetos\speednetwork\apps\sales\views.py", line 39, in Index
    conheceu_empresa_mes_count = conheceu_empresa_mes_count()
UnboundLocalError: local variable 'conheceu_empresa_mes_count' referenced before assignment
"GET /vendas/ HTTP/1.1" 500 80311
Internal Server Error: /vendas/
Traceback (most recent call last):
  File "C:\projetos\speednetwork\venv\lib\site-packages\django\core\handlers\exception.py", line 34, in inner
    response = get_response(request)
  File "C:\projetos\speednetwork\venv\lib\site-packages\django\core\handlers\base.py", line 115, in _get_response
    response = self.process_exception_by_middleware(e, request)
  File "C:\projetos\speednetwork\venv\lib\site-packages\django\core\handlers\base.py", line 113, in _get_response
    response = wrapped_callback(request, *callback_args, **callback_kwargs)
  File "C:\projetos\speednetwork\venv\lib\site-packages\django\contrib\auth\decorators.py", line 21, in _wrapped_view
    return view_func(request, *args, **kwargs)
  File "C:\projetos\speednetwork\apps\sales\views.py", line 39, in Index
    conheceu_empresa_mes_count = conheceu_empresa_mes_count()
UnboundLocalError: local variable 'conheceu_empresa_mes_count' referenced before assignment
"GET /vendas/ HTTP/1.1" 500 80055
Internal Server Error: /vendas/
Traceback (most recent call last):
  File "C:\projetos\speednetwork\venv\lib\site-packages\django\core\handlers\exception.py", line 34, in inner
    response = get_response(request)
  File "C:\projetos\speednetwork\venv\lib\site-packages\django\core\handlers\base.py", line 115, in _get_response
    response = self.process_exception_by_middleware(e, request)
  File "C:\projetos\speednetwork\venv\lib\site-packages\django\core\handlers\base.py", line 113, in _get_response
    response = wrapped_callback(request, *callback_args, **callback_kwargs)
  File "C:\projetos\speednetwork\venv\lib\site-packages\django\contrib\auth\decorators.py", line 21, in _wrapped_view
    return view_func(request, *args, **kwargs)
  File "C:\projetos\speednetwork\apps\sales\views.py", line 39, in Index
    conheceu_empresa_mes_count = conheceu_empresa_mes_count()
UnboundLocalError: local variable 'conheceu_empresa_mes_count' referenced before assignment
"GET /vendas/ HTTP/1.1" 500 80055
Internal Server Error: /
Traceback (most recent call last):
  File "C:\projetos\speednetwork\venv\lib\site-packages\django\core\handlers\exception.py", line 34, in inner
    response = get_response(request)
  File "C:\projetos\speednetwork\venv\lib\site-packages\django\core\handlers\base.py", line 115, in _get_response
    response = self.process_exception_by_middleware(e, request)
  File "C:\projetos\speednetwork\venv\lib\site-packages\django\core\handlers\base.py", line 113, in _get_response
    response = wrapped_callback(request, *callback_args, **callback_kwargs)
  File "C:\projetos\speednetwork\venv\lib\site-packages\django\contrib\auth\decorators.py", line 21, in _wrapped_view
    return view_func(request, *args, **kwargs)
  File "C:\projetos\speednetwork\apps\core\views.py", line 92, in Index
    install_mes = instalacoes_mes_atual()
NameError: name 'instalacoes_mes_atual' is not defined
"GET / HTTP/1.1" 500 80542
Internal Server Error: /
Traceback (most recent call last):
  File "C:\projetos\speednetwork\venv\lib\site-packages\django\core\handlers\exception.py", line 34, in inner
    response = get_response(request)
  File "C:\projetos\speednetwork\venv\lib\site-packages\django\core\handlers\base.py", line 115, in _get_response
    response = self.process_exception_by_middleware(e, request)
  File "C:\projetos\speednetwork\venv\lib\site-packages\django\core\handlers\base.py", line 113, in _get_response
    response = wrapped_callback(request, *callback_args, **callback_kwargs)
  File "C:\projetos\speednetwork\venv\lib\site-packages\django\contrib\auth\decorators.py", line 21, in _wrapped_view
    return view_func(request, *args, **kwargs)
  File "C:\projetos\speednetwork\apps\core\views.py", line 92, in Index
    install_mes = instalacoes_mes_atual()
NameError: name 'instalacoes_mes_atual' is not defined
"GET / HTTP/1.1" 500 80678
Internal Server Error: /
Traceback (most recent call last):
  File "C:\projetos\speednetwork\venv\lib\site-packages\django\core\handlers\exception.py", line 34, in inner
    response = get_response(request)
  File "C:\projetos\speednetwork\venv\lib\site-packages\django\core\handlers\base.py", line 115, in _get_response
    response = self.process_exception_by_middleware(e, request)
  File "C:\projetos\speednetwork\venv\lib\site-packages\django\core\handlers\base.py", line 113, in _get_response
    response = wrapped_callback(request, *callback_args, **callback_kwargs)
  File "C:\projetos\speednetwork\venv\lib\site-packages\django\contrib\auth\decorators.py", line 21, in _wrapped_view
    return view_func(request, *args, **kwargs)
  File "C:\projetos\speednetwork\apps\core\views.py", line 171, in Index
    'install_mes': install_mes,
NameError: name 'install_mes' is not defined
"GET / HTTP/1.1" 500 87221
Internal Server Error: /servicos/editar-servico/27
Traceback (most recent call last):
  File "C:\projetos\speednetwork\venv\lib\site-packages\django\core\handlers\exception.py", line 34, in inner
    response = get_response(request)
  File "C:\projetos\speednetwork\venv\lib\site-packages\django\core\handlers\base.py", line 115, in _get_response
    response = self.process_exception_by_middleware(e, request)
  File "C:\projetos\speednetwork\venv\lib\site-packages\django\core\handlers\base.py", line 113, in _get_response
    response = wrapped_callback(request, *callback_args, **callback_kwargs)
  File "C:\projetos\speednetwork\apps\services\views.py", line 134, in EditarServico
    return render(request, 'services/editar-servico.html', {'form': form})
  File "C:\projetos\speednetwork\venv\lib\site-packages\django\shortcuts.py", line 19, in render
    content = loader.render_to_string(template_name, context, request, using=using)
  File "C:\projetos\speednetwork\venv\lib\site-packages\django\template\loader.py", line 62, in render_to_string
    return template.render(context, request)
  File "C:\projetos\speednetwork\venv\lib\site-packages\django\template\backends\django.py", line 61, in render
    return self.template.render(context)
  File "C:\projetos\speednetwork\venv\lib\site-packages\django\template\base.py", line 171, in render
    return self._render(context)
  File "C:\projetos\speednetwork\venv\lib\site-packages\django\template\base.py", line 163, in _render
    return self.nodelist.render(context)
  File "C:\projetos\speednetwork\venv\lib\site-packages\django\template\base.py", line 936, in render
    bit = node.render_annotated(context)
  File "C:\projetos\speednetwork\venv\lib\site-packages\django\template\base.py", line 903, in render_annotated
    return self.render(context)
  File "C:\projetos\speednetwork\venv\lib\site-packages\django\template\loader_tags.py", line 150, in render
    return compiled_parent._render(context)
  File "C:\projetos\speednetwork\venv\lib\site-packages\django\template\base.py", line 163, in _render
    return self.nodelist.render(context)
  File "C:\projetos\speednetwork\venv\lib\site-packages\django\template\base.py", line 936, in render
    bit = node.render_annotated(context)
  File "C:\projetos\speednetwork\venv\lib\site-packages\django\template\base.py", line 903, in render_annotated
    return self.render(context)
  File "C:\projetos\speednetwork\venv\lib\site-packages\django\template\loader_tags.py", line 62, in render
    result = block.nodelist.render(context)
  File "C:\projetos\speednetwork\venv\lib\site-packages\django\template\base.py", line 936, in render
    bit = node.render_annotated(context)
  File "C:\projetos\speednetwork\venv\lib\site-packages\django\template\base.py", line 903, in render_annotated
    return self.render(context)
  File "C:\projetos\speednetwork\venv\lib\site-packages\django\template\base.py", line 986, in render
    output = self.filter_expression.resolve(context)
  File "C:\projetos\speednetwork\venv\lib\site-packages\django\template\base.py", line 697, in resolve
    new_obj = func(obj, *arg_vals)
  File "C:\projetos\speednetwork\venv\lib\site-packages\crispy_forms\templatetags\crispy_forms_filters.py", line 102, in as_crispy_field
    raise CrispyError("|as_crispy_field got passed an invalid or inexistent field")
crispy_forms.exceptions.CrispyError: |as_crispy_field got passed an invalid or inexistent field
"GET /servicos/editar-servico/27 HTTP/1.1" 500 169726
Internal Server Error: /vendas/agendar-instalacao/32
Traceback (most recent call last):
  File "C:\projetos\speednetwork\venv\lib\site-packages\django\core\handlers\exception.py", line 34, in inner
    response = get_response(request)
  File "C:\projetos\speednetwork\venv\lib\site-packages\django\core\handlers\base.py", line 115, in _get_response
    response = self.process_exception_by_middleware(e, request)
  File "C:\projetos\speednetwork\venv\lib\site-packages\django\core\handlers\base.py", line 113, in _get_response
    response = wrapped_callback(request, *callback_args, **callback_kwargs)
  File "C:\projetos\speednetwork\venv\lib\site-packages\django\contrib\auth\decorators.py", line 21, in _wrapped_view
    return view_func(request, *args, **kwargs)
  File "C:\projetos\speednetwork\apps\sales\views.py", line 240, in InstalacaoAgendar
    return render(request, 'sales/agendar-instalacao.html', {'form': form})
  File "C:\projetos\speednetwork\venv\lib\site-packages\django\shortcuts.py", line 19, in render
    content = loader.render_to_string(template_name, context, request, using=using)
  File "C:\projetos\speednetwork\venv\lib\site-packages\django\template\loader.py", line 62, in render_to_string
    return template.render(context, request)
  File "C:\projetos\speednetwork\venv\lib\site-packages\django\template\backends\django.py", line 61, in render
    return self.template.render(context)
  File "C:\projetos\speednetwork\venv\lib\site-packages\django\template\base.py", line 171, in render
    return self._render(context)
  File "C:\projetos\speednetwork\venv\lib\site-packages\django\template\base.py", line 163, in _render
    return self.nodelist.render(context)
  File "C:\projetos\speednetwork\venv\lib\site-packages\django\template\base.py", line 936, in render
    bit = node.render_annotated(context)
  File "C:\projetos\speednetwork\venv\lib\site-packages\django\template\base.py", line 903, in render_annotated
    return self.render(context)
  File "C:\projetos\speednetwork\venv\lib\site-packages\django\template\loader_tags.py", line 150, in render
    return compiled_parent._render(context)
  File "C:\projetos\speednetwork\venv\lib\site-packages\django\template\base.py", line 163, in _render
    return self.nodelist.render(context)
  File "C:\projetos\speednetwork\venv\lib\site-packages\django\template\base.py", line 936, in render
    bit = node.render_annotated(context)
  File "C:\projetos\speednetwork\venv\lib\site-packages\django\template\base.py", line 903, in render_annotated
    return self.render(context)
  File "C:\projetos\speednetwork\venv\lib\site-packages\django\template\loader_tags.py", line 62, in render
    result = block.nodelist.render(context)
  File "C:\projetos\speednetwork\venv\lib\site-packages\django\template\base.py", line 936, in render
    bit = node.render_annotated(context)
  File "C:\projetos\speednetwork\venv\lib\site-packages\django\template\base.py", line 903, in render_annotated
    return self.render(context)
  File "C:\projetos\speednetwork\venv\lib\site-packages\django\template\base.py", line 986, in render
    output = self.filter_expression.resolve(context)
  File "C:\projetos\speednetwork\venv\lib\site-packages\django\template\base.py", line 697, in resolve
    new_obj = func(obj, *arg_vals)
  File "C:\projetos\speednetwork\venv\lib\site-packages\crispy_forms\templatetags\crispy_forms_filters.py", line 102, in as_crispy_field
    raise CrispyError("|as_crispy_field got passed an invalid or inexistent field")
crispy_forms.exceptions.CrispyError: |as_crispy_field got passed an invalid or inexistent field
"GET /vendas/agendar-instalacao/32 HTTP/1.1" 500 167765
Internal Server Error: /vendas/agendar-instalacao/32
Traceback (most recent call last):
  File "C:\projetos\speednetwork\venv\lib\site-packages\django\core\handlers\exception.py", line 34, in inner
    response = get_response(request)
  File "C:\projetos\speednetwork\venv\lib\site-packages\django\core\handlers\base.py", line 115, in _get_response
    response = self.process_exception_by_middleware(e, request)
  File "C:\projetos\speednetwork\venv\lib\site-packages\django\core\handlers\base.py", line 113, in _get_response
    response = wrapped_callback(request, *callback_args, **callback_kwargs)
  File "C:\projetos\speednetwork\venv\lib\site-packages\django\contrib\auth\decorators.py", line 21, in _wrapped_view
    return view_func(request, *args, **kwargs)
  File "C:\projetos\speednetwork\apps\sales\views.py", line 240, in InstalacaoAgendar
    return render(request, 'sales/agendar-instalacao.html', {'form': form})
  File "C:\projetos\speednetwork\venv\lib\site-packages\django\shortcuts.py", line 19, in render
    content = loader.render_to_string(template_name, context, request, using=using)
  File "C:\projetos\speednetwork\venv\lib\site-packages\django\template\loader.py", line 62, in render_to_string
    return template.render(context, request)
  File "C:\projetos\speednetwork\venv\lib\site-packages\django\template\backends\django.py", line 61, in render
    return self.template.render(context)
  File "C:\projetos\speednetwork\venv\lib\site-packages\django\template\base.py", line 171, in render
    return self._render(context)
  File "C:\projetos\speednetwork\venv\lib\site-packages\django\template\base.py", line 163, in _render
    return self.nodelist.render(context)
  File "C:\projetos\speednetwork\venv\lib\site-packages\django\template\base.py", line 936, in render
    bit = node.render_annotated(context)
  File "C:\projetos\speednetwork\venv\lib\site-packages\django\template\base.py", line 903, in render_annotated
    return self.render(context)
  File "C:\projetos\speednetwork\venv\lib\site-packages\django\template\loader_tags.py", line 150, in render
    return compiled_parent._render(context)
  File "C:\projetos\speednetwork\venv\lib\site-packages\django\template\base.py", line 163, in _render
    return self.nodelist.render(context)
  File "C:\projetos\speednetwork\venv\lib\site-packages\django\template\base.py", line 936, in render
    bit = node.render_annotated(context)
  File "C:\projetos\speednetwork\venv\lib\site-packages\django\template\base.py", line 903, in render_annotated
    return self.render(context)
  File "C:\projetos\speednetwork\venv\lib\site-packages\django\template\loader_tags.py", line 62, in render
    result = block.nodelist.render(context)
  File "C:\projetos\speednetwork\venv\lib\site-packages\django\template\base.py", line 936, in render
    bit = node.render_annotated(context)
  File "C:\projetos\speednetwork\venv\lib\site-packages\django\template\base.py", line 903, in render_annotated
    return self.render(context)
  File "C:\projetos\speednetwork\venv\lib\site-packages\django\template\base.py", line 986, in render
    output = self.filter_expression.resolve(context)
  File "C:\projetos\speednetwork\venv\lib\site-packages\django\template\base.py", line 697, in resolve
    new_obj = func(obj, *arg_vals)
  File "C:\projetos\speednetwork\venv\lib\site-packages\crispy_forms\templatetags\crispy_forms_filters.py", line 102, in as_crispy_field
    raise CrispyError("|as_crispy_field got passed an invalid or inexistent field")
crispy_forms.exceptions.CrispyError: |as_crispy_field got passed an invalid or inexistent field
"GET /vendas/agendar-instalacao/32 HTTP/1.1" 500 167765
Internal Server Error: /vendas/agendar-instalacao/32
Traceback (most recent call last):
  File "C:\projetos\speednetwork\venv\lib\site-packages\django\core\handlers\exception.py", line 34, in inner
    response = get_response(request)
  File "C:\projetos\speednetwork\venv\lib\site-packages\django\core\handlers\base.py", line 115, in _get_response
    response = self.process_exception_by_middleware(e, request)
  File "C:\projetos\speednetwork\venv\lib\site-packages\django\core\handlers\base.py", line 113, in _get_response
    response = wrapped_callback(request, *callback_args, **callback_kwargs)
  File "C:\projetos\speednetwork\venv\lib\site-packages\django\contrib\auth\decorators.py", line 21, in _wrapped_view
    return view_func(request, *args, **kwargs)
  File "C:\projetos\speednetwork\apps\sales\views.py", line 240, in InstalacaoAgendar
    return render(request, 'sales/agendar-instalacao.html', {'form': form})
  File "C:\projetos\speednetwork\venv\lib\site-packages\django\shortcuts.py", line 19, in render
    content = loader.render_to_string(template_name, context, request, using=using)
  File "C:\projetos\speednetwork\venv\lib\site-packages\django\template\loader.py", line 62, in render_to_string
    return template.render(context, request)
  File "C:\projetos\speednetwork\venv\lib\site-packages\django\template\backends\django.py", line 61, in render
    return self.template.render(context)
  File "C:\projetos\speednetwork\venv\lib\site-packages\django\template\base.py", line 171, in render
    return self._render(context)
  File "C:\projetos\speednetwork\venv\lib\site-packages\django\template\base.py", line 163, in _render
    return self.nodelist.render(context)
  File "C:\projetos\speednetwork\venv\lib\site-packages\django\template\base.py", line 936, in render
    bit = node.render_annotated(context)
  File "C:\projetos\speednetwork\venv\lib\site-packages\django\template\base.py", line 903, in render_annotated
    return self.render(context)
  File "C:\projetos\speednetwork\venv\lib\site-packages\django\template\loader_tags.py", line 150, in render
    return compiled_parent._render(context)
  File "C:\projetos\speednetwork\venv\lib\site-packages\django\template\base.py", line 163, in _render
    return self.nodelist.render(context)
  File "C:\projetos\speednetwork\venv\lib\site-packages\django\template\base.py", line 936, in render
    bit = node.render_annotated(context)
  File "C:\projetos\speednetwork\venv\lib\site-packages\django\template\base.py", line 903, in render_annotated
    return self.render(context)
  File "C:\projetos\speednetwork\venv\lib\site-packages\django\template\loader_tags.py", line 62, in render
    result = block.nodelist.render(context)
  File "C:\projetos\speednetwork\venv\lib\site-packages\django\template\base.py", line 936, in render
    bit = node.render_annotated(context)
  File "C:\projetos\speednetwork\venv\lib\site-packages\django\template\base.py", line 903, in render_annotated
    return self.render(context)
  File "C:\projetos\speednetwork\venv\lib\site-packages\django\template\base.py", line 986, in render
    output = self.filter_expression.resolve(context)
  File "C:\projetos\speednetwork\venv\lib\site-packages\django\template\base.py", line 697, in resolve
    new_obj = func(obj, *arg_vals)
  File "C:\projetos\speednetwork\venv\lib\site-packages\crispy_forms\templatetags\crispy_forms_filters.py", line 102, in as_crispy_field
    raise CrispyError("|as_crispy_field got passed an invalid or inexistent field")
crispy_forms.exceptions.CrispyError: |as_crispy_field got passed an invalid or inexistent field
"GET /vendas/agendar-instalacao/32 HTTP/1.1" 500 167761
Internal Server Error: /vendas/agendar-instalacao/32
Traceback (most recent call last):
  File "C:\projetos\speednetwork\venv\lib\site-packages\django\core\handlers\exception.py", line 34, in inner
    response = get_response(request)
  File "C:\projetos\speednetwork\venv\lib\site-packages\django\core\handlers\base.py", line 115, in _get_response
    response = self.process_exception_by_middleware(e, request)
  File "C:\projetos\speednetwork\venv\lib\site-packages\django\core\handlers\base.py", line 113, in _get_response
    response = wrapped_callback(request, *callback_args, **callback_kwargs)
  File "C:\projetos\speednetwork\venv\lib\site-packages\django\contrib\auth\decorators.py", line 21, in _wrapped_view
    return view_func(request, *args, **kwargs)
  File "C:\projetos\speednetwork\apps\sales\views.py", line 240, in InstalacaoAgendar
    return render(request, 'sales/agendar-instalacao.html', {'form': form})
  File "C:\projetos\speednetwork\venv\lib\site-packages\django\shortcuts.py", line 19, in render
    content = loader.render_to_string(template_name, context, request, using=using)
  File "C:\projetos\speednetwork\venv\lib\site-packages\django\template\loader.py", line 62, in render_to_string
    return template.render(context, request)
  File "C:\projetos\speednetwork\venv\lib\site-packages\django\template\backends\django.py", line 61, in render
    return self.template.render(context)
  File "C:\projetos\speednetwork\venv\lib\site-packages\django\template\base.py", line 171, in render
    return self._render(context)
  File "C:\projetos\speednetwork\venv\lib\site-packages\django\template\base.py", line 163, in _render
    return self.nodelist.render(context)
  File "C:\projetos\speednetwork\venv\lib\site-packages\django\template\base.py", line 936, in render
    bit = node.render_annotated(context)
  File "C:\projetos\speednetwork\venv\lib\site-packages\django\template\base.py", line 903, in render_annotated
    return self.render(context)
  File "C:\projetos\speednetwork\venv\lib\site-packages\django\template\loader_tags.py", line 150, in render
    return compiled_parent._render(context)
  File "C:\projetos\speednetwork\venv\lib\site-packages\django\template\base.py", line 163, in _render
    return self.nodelist.render(context)
  File "C:\projetos\speednetwork\venv\lib\site-packages\django\template\base.py", line 936, in render
    bit = node.render_annotated(context)
  File "C:\projetos\speednetwork\venv\lib\site-packages\django\template\base.py", line 903, in render_annotated
    return self.render(context)
  File "C:\projetos\speednetwork\venv\lib\site-packages\django\template\loader_tags.py", line 62, in render
    result = block.nodelist.render(context)
  File "C:\projetos\speednetwork\venv\lib\site-packages\django\template\base.py", line 936, in render
    bit = node.render_annotated(context)
  File "C:\projetos\speednetwork\venv\lib\site-packages\django\template\base.py", line 903, in render_annotated
    return self.render(context)
  File "C:\projetos\speednetwork\venv\lib\site-packages\django\template\base.py", line 986, in render
    output = self.filter_expression.resolve(context)
  File "C:\projetos\speednetwork\venv\lib\site-packages\django\template\base.py", line 697, in resolve
    new_obj = func(obj, *arg_vals)
  File "C:\projetos\speednetwork\venv\lib\site-packages\crispy_forms\templatetags\crispy_forms_filters.py", line 102, in as_crispy_field
    raise CrispyError("|as_crispy_field got passed an invalid or inexistent field")
crispy_forms.exceptions.CrispyError: |as_crispy_field got passed an invalid or inexistent field
"GET /vendas/agendar-instalacao/32 HTTP/1.1" 500 167761
